Workbook

Sheet Resumen
A1: Presupuesto de IA, infraestructura y datos
A2: AgroScout IA · CITEagroindustrial Chavimochic · Huawei Cloud LA-Santiago · elaborado 2026-08-14
A4: Bloque | B4: Mínimo (US$) | C4: Esperado (US$) | D4: Máximo (US$) | E4: Qué hay detrás
A5: Consumo de IA — ModelArts MaaS | B5: ='Costos-IA'!$D$32 | C5: ='Costos-IA'!$E$32 | D5: ='Costos-IA'!$F$32 | E5: Coste por etapa MEDIDO en etapas_ejecucion. Tres de las cinco etapas corren sobre glm-5.2, que es el modelo caro.
A6: Suscripciones de terceros | B6: =Suscripciones!$F$17 | C6: =Suscripciones!$G$17 | D6: =Suscripciones!$H$17 | E6: Lo que hoy está contratado o con clave activa en .env. Casi todo está en plan gratuito.
A7: Infraestructura Huawei (sin MongoDB) | B7: =Infraestructura!$J$31 | C7: =Infraestructura!$K$31 | D7: =Infraestructura!$L$31 | E7: ECS 4 vCPU/8 GB, RDS PostgreSQL nodo único, EVS 100 GB, OBS, EIP, CBR, LTS y CES.
A8: MongoDB para Open Food Facts | B8: ='MongoDB-OFF'!$D$89 | C8: ='MongoDB-OFF'!$E$89 | D8: ='MongoDB-OFF'!$F$89 | E8: Opción seleccionada en la hoja MongoDB-OFF (celda B93). Es la pieza más cara del añadido.
A10: TOTAL MENSUAL (US$) | B10: =SUM(B5:B8) | C10: =SUM(C5:C8) | D10: =SUM(D5:D8)
A11: TOTAL MENSUAL (S/) | B11: =B10*Parametros!$B$8 | C11: =C10*Parametros!$B$8 | D11: =D10*Parametros!$B$8
A12: TOTAL ANUAL (US$) | B12: =B10*12 | C12: =C10*12 | D12: =D10*12
A13: TOTAL ANUAL con compromiso anual (US$) | B13: =B10*12*(1-Parametros!$B$10) | C13: =C10*12*(1-Parametros!$B$10) | D13: =D10*12*(1-Parametros!$B$10)
A15: Las cinco cosas que hay que saber antes de leer las cifras
A16: 1. El coste de IA está MEDIDO, no estimado. En etapas_ejecucion hay llamadas reales con su recuento de tokens: la etapa 3 (InsightMercado) consume 6.377 tokens de entrada y 2.004 de salida sobre glm-5.2, y eso son US$ 0,1039 en una sola etapa. Las tarifas salen de config/tarifas_llm.json.
A17: 2. La etapa 3 se llevó el 50 % de la factura de IA por un accidente, no por diseño. El plan la había puesto en glm-5.0 (11× más barato), pero ModelArts responde 404 'Invalid model' a glm-5.0 y glm-4.7 (adaptadores/redactor_glm.py:24-27), así que quedó en glm-5.2. Es la palanca de ahorro más grande del proyecto: la hoja Costos-IA la cuantifica.
A18: 3. El plan gratuito NO es barato. Con la etapa 3 en glm-5.2, un run 'gratuito' cuesta US$ 0,104: el tope de US$ 2/mes por usuario gratuito son 19 consultas, no las que se supuso al escribirlo.
A19: 4. MongoDB con Open Food Facts entero es una máquina distinta, no un contenedor más. El volcado son 14,4 GiB comprimidos y 4.680.925 productos MEDIDOS el 2026-08-14; en disco son ~27 GB y el working set no cabe en el ECS de 8 GB que ya está ocupado por bge-m3. La hoja MongoDB-OFF costea las tres salidas.
A20: 5. Los precios de Huawei son ENTRADAS, no hechos. Huawei no publica tarifas en HTML: viven dentro de su calculador JavaScript. Cada precio es una celda amarilla con rango; la hoja Precios-Huawei dice cómo verificar cada uno en minutos y todo el libro se recalcula solo.
A22: Código de colores
A23: Amarillo — celda de entrada: la edita usted con el dato del calculador o del contrato.
A24: Verde — dato MEDIDO en este proyecto o contra la fuente real. No es una estimación.
A25: Naranja — total calculado. Son fórmulas: no escribir encima.
A26: Rojo — hallazgo o alerta: algo que hay que decidir, no solo leer.

Sheet Costos-IA
A1: Costo promedio de IA — ModelArts MaaS (Huawei)
A2: Tokens y coste por etapa MEDIDOS en etapas_ejecucion (agroscout.db, 306 filas). Tarifas de config/tarifas_llm.json.
A4: A · TARIFAS DE MODELO — ModelArts MaaS, región ap-southeast-1 (Singapur)
B5: Modelo | C5: Estado en MaaS | D5: US$/1k entrada | E5: US$/1k salida | J5: Origen y observación
B6: deepseek-v4-flash | C6: En uso · etapas 1 y 2a | D6: 0.000135 | E6: 0.000539 | J6: config/tarifas_llm.json. El modelo económico: 74× más barato en entrada que glm-5.2.
B7: glm-5.2 | C7: En uso · etapas 3, 4 y 5 | D7: 0.01 | E7: 0.02 | J7: config/tarifas_llm.json. Modelo insignia. Es el que se lleva la factura.
B8: glm-5.0 | C8: NO DISPONIBLE (404) | D8: 0.000539 | E8: 0.002965 | J8: El plan puso aquí la etapa 3. ModelArts responde 'ModelArts.81009 Invalid model' (adaptadores/redactor_glm.py:24-27). La tarifa está en el repo pero el modelo no se puede llamar.
B9: glm-4.7 | C9: NO DISPONIBLE (404) | D9: 0.003 | E9: 0.006 | J9: Mismo caso. Deprecado en el proyecto.
A11: B · COSTO POR ETAPA — el DAG de una consulta
A12: Etapa | B12: Qué hace | C12: Modelo | D12: Tokens ent. | E12: Tokens sal. | F12: US$/1k ent. | G12: US$/1k sal. | H12: Costo/llamada | I12: Latencia (s) | J12: Origen del dato
A13: 1 | B13: InterpretarInsumo | C13: deepseek-v4-flash | D13: 606 | E13: 548 | F13: =$D$6 | G13: =$E$6 | H13: =D13/1000*F13+E13/1000*G13 | I13: 34.2 | J13: MEDIDO: llamada en frío real en etapas_ejecucion (n=2). Traduce el término en español e identifica la materia prima.
A14: 2a | B14: MatchProductos | C14: deepseek-v4-flash | D14: 600 | E14: 400 | F14: =$D$6 | G14: =$E$6 | H14: =D14/1000*F14+E14/1000*G14 | I14: 15.5 | J14: ESTIMADO sobre el mismo modelo y un prompt equivalente. Las filas medidas de 2a no llevan tokens: el emparejamiento resuelto por búsqueda vectorial no llama al modelo.
A15: 2b | B15: MapaComercial | C15: — sin LLM — | D15: 0 | E15: 0 | F15: 0 | G15: 0 | H15: 0 | I15: 0.2 | J15: MEDIDO: 0,21 s y cero tokens. casos_de_uso/etapas/mapear_comercio.py no llama a ningún modelo; el 'modelo' que registra es una etiqueta heredada del ejecutor.
A16: 3 | B16: InsightMercado | C16: glm-5.2 | D16: 6377 | E16: 2004 | F16: =$D$7 | G16: =$E$7 | H16: =D16/1000*F16+E16/1000*G16 | I16: 123.2 | J16: MEDIDO: llamada en frío real (n=2). Recibe los 30 productos con sus ingredientes: por eso son 6.377 tokens de entrada. ES LA ETAPA MÁS CARA DEL SISTEMA.
A17: 4 | B17: Formulación (premium) | C17: glm-5.2 | D17: 2500 | E17: 1200 | F17: =$D$7 | G17: =$E$7 | H17: =D17/1000*F17+E17/1000*G17 | I17: 30 | J17: ESTIMADO: aún no hay filas en frío de la etapa separada. Calibrado para que el total premium caiga dentro del rango MEDIDO de US$ 0,19-0,23 anotado en .env.example.
A18: 5 | B18: Regulación (premium) | C18: glm-5.2 | D18: 3000 | E18: 1400 | F18: =$D$7 | G18: =$E$7 | H18: =D18/1000*F18+E18/1000*G18 | I18: 35 | J18: ESTIMADO: incluye el contexto del corpus regulatorio (eCFR + DIGESA). Misma calibración que la etapa 4.
A19: 6 | B19: Informe PDF | C19: — sin LLM — | D19: 0 | E19: 0 | F19: 0 | G19: 0 | H19: 0 | I19: 3 | J19: MEDIDO: WeasyPrint/xhtml2pdf. Cero tokens; ~3 s de CPU que bloquean el bucle de eventos.
B21: RUN GRATUITO (etapas 1, 2a, 2b, 3) | D21: =SUM(D13:D16) | E21: =SUM(E13:E16) | H21: =SUM(H13:H16) | I21: =SUM(I13:I16) | J21: El paywall corta antes de la etapa 4. La etapa 3 aporta el 99 % de este importe.
B22: RUN PREMIUM (etapas 1 a 6) | D22: =SUM(D13:D19) | E22: =SUM(E13:E19) | H22: =SUM(H13:H19) | I22: =SUM(I13:I19) | J22: Contraste: .env.example anota US$ 0,19-0,23 MEDIDO el 2026-08-02. Si esta celda se sale del rango, revise las etapas 4 y 5.
A23: + | B23: Agente web N3 (opcional, S8/S10) | C23: glm-5.2 | D23: 1800 | E23: 350 | F23: =$D$7 | G23: =$E$7 | H23: =(D23/1000*F23+E23/1000*G23)*3 | I23: 60 | J23: ×3 URL en serie por run. MEDIDO: 6.000 caracteres de HTML por extracción (agente.py:121) y 15-42 s por llamada. Solo se paga cuando la ficha NO trae JSON-LD; con datos estructurados la extracción es gratis y en milisegundos.
A25: C · COSTO MENSUAL DE IA
B26: Concepto | D26: Mínimo | E26: Esperado | F26: Máximo | J26: Cómo se calcula
B27: Runs premium al mes | D27: =Parametros!$B$11*0.5 | E27: =Parametros!$B$11 | F27: =Parametros!$B$11*2 | J27: Parámetro editable. Mínimo = medio volumen; máximo = el doble.
B28: Runs gratuitos al mes | D28: =Parametros!$B$12*0.5 | E28: =Parametros!$B$12 | F28: =Parametros!$B$12*2 | J28: Parámetro editable.
B29: Costo bruto premium | D29: =D27*$H$22 | E29: =E27*$H$22 | F29: =F27*$H$22 | J29: Runs × costo por run premium.
B30: Costo bruto gratuito | D30: =D28*$H$21 | E30: =E28*$H$21 | F30: =F28*$H$21 | J30: Runs × costo por run gratuito. Esta línea sorprende a todo el mundo.
B31: Ahorro por cache de respuestas | D31: =-(D30+D29)*Parametros!$B$13 | E31: =-(E30+E29)*Parametros!$B$13 | F31: =-(F30+F29)*Parametros!$B$13 | J31: MEDIDO: 51,4 % de acierto (109 de 212 filas de etapa con modelo). El cache indexa por (entrada, modelo, etapa, snapshot_version), así que solo sirve mientras el snapshot no cambie.
B32: COSTO MENSUAL DE IA (US$) | D32: =D29+D30+D31 | E32: =E29+E30+E31 | F32: =F29+F30+F31 | J32: Bruto premium + bruto gratuito − ahorro de cache.
B33: Costo medio por consulta (todas) | D33: =D32/(D27+D28) | E33: =E32/(E27+E28) | F33: =F32/(F27+F28) | J33: El número que se compara con el precio de la suscripción.
B34: Costo por 1.000 consultas | D34: =D33*1000 | E34: =E33*1000 | F34: =F33*1000 | J34: Para hablar de escala sin decimales.
A36: D · CONTRA LOS TOPES QUE YA ESTÁN EN EL CÓDIGO (.env)
B37: Tope configurado | C37: Valor | D37: Runs que caben | J37: Qué significa
B38: PRESUPUESTO_RUN_USD | C38: 0.25 | D38: =C38/$H$22 | J38: Tope por run. Un run premium mide US$ 0,21: cabe, pero con poco margen. Si la etapa 3 recibe más productos, el run se corta a la mitad.
B39: PRESUPUESTO_USUARIO_MES_USD (gratuito) | C39: 2 | D39: =C39/$H$21 | J39: El plan gratuito da para 19 consultas al mes por usuario, no las que se supusieron al escribir el número.
B40: PRESUPUESTO_PREMIUM_MES_USD | C40: 10 | D40: =C40/$H$22 | J40: 47 consultas premium al mes por usuario.
B41: PRESUPUESTO_GLOBAL_MES_USD (kill-switch) | C41: 10 | D41: =C41/$H$22 | J41: TOPE PARA TODA LA INSTITUCIÓN. Al superarse nadie ejecuta LLM: los runs siguen devolviendo 200 con informe parcial y motivo 'presupuesto'. Sobra para el CDR; se queda corto para uso real.
A43: E · LA PALANCA DE AHORRO: qué pasa si la etapa 3 no corre en glm-5.2
B44: Escenario para la etapa 3 | C44: Modelo | D44: Costo etapa 3 | E44: Costo run gratuito | F44: Costo run premium | G44: Ahorro mensual | J44: Qué haría falta
B45: Hoy — como está desplegado | C45: glm-5.2 | D45: =$H$16 | E45: =$H$21 | F45: =$H$22 | G45: 0 | J45: Nada. Es el estado actual: adaptadores/redactor_glm.py apunta la etapa 3 a glm-5.2.
B46: Etapa 3 a deepseek-v4-flash | C46: deepseek-v4-flash | D46: =$D$16/1000*$D$6+$E$16/1000*$E$6 | E46: =$H$21-$H$16+D46 | F46: =$H$22-$H$16+D46 | G46: =(E45-E46)*Parametros!$B$12+(F45-F46)*Parametros!$B$11 | J46: Un cambio de una línea, pero hay que revalidar la calidad del insight: es la etapa que el CITE lee. Medir contra el golden set de los 5 insumos antes de tocarla.
...

Sheet Suscripciones
A1: Suscripciones y servicios de terceros
A2: Lo que hoy está contratado o tiene clave activa en .env, con su modelo de cobro. Verificado contra el .env el 2026-08-14 (sin exponer valores).
A4: Servicio | B4: Para qué se usa | C4: Plan actual | D4: Modelo de cobro | E4: Estado de la clave | F4: US$/mes mín | G4: US$/mes esp. | H4: US$/mes máx | I4: Nota y qué decidir
A5: Huawei ModelArts MaaS | B5: Los 5 modelos del DAG (deepseek-v4-flash y glm-5.2) y el agente extractor | C5: Pago por token | D5: Por token consumido | E5: CONFIGURADA | F5: ='Costos-IA'!$D$32 | G5: ='Costos-IA'!$E$32 | H5: ='Costos-IA'!$F$32 | I5: No tiene cuota fija: es el consumo de la hoja Costos-IA. Vive en ap-southeast-1 (Singapur).
A6: Huawei Cloud (infraestructura) | B6: ECS, RDS, EVS, OBS, EIP, CBR, LTS, CES | C6: Pago por uso | D6: Por hora y por GB-mes | E6: Cuenta International requerida | F6: =Infraestructura!$J$31 | G6: =Infraestructura!$K$31 | H6: =Infraestructura!$L$31 | I6: Detalle línea por línea en la hoja Infraestructura. El compromiso anual descuenta 30-40 %.
A7: Supabase | B7: Postgres gestionado, Auth y Storage de PDFs (Semana 3) | C7: Free o Pro | D7: Cuota fija mensual | E7: CONFIGURADA (6 variables) | F7: 0 | G7: 0 | H7: 25 | I7: SALE DE LA FOTO cuando entre RDS (decisión de INFRA-HUAWEI-CLOUD.md §1). Mientras tanto sigue activa y es la base real. Coste 0 en Free; US$ 25 en Pro.
A8: Tavily | B8: Búsqueda web del agente N3 (fase F4 / S10) | C8: Free (1.000 créditos) | D8: Por crédito o cuota | E8: CONFIGURADA | F8: 0 | G8: 0 | H8: 30 | I8: Gratuito hasta 1.000 créditos/mes; el plan Researcher son US$ 30/mes por 4.000 créditos, o US$ 0,008 por crédito a demanda. Una búsqueda básica = 1 crédito. VERIFICAR el consumo real antes de comprometer.
A9: Bright Data Web Unlocker | B9: Reserva cuando una tienda responde 403 (góndola S8) | C9: Pago por uso · zona web_api_ai | D9: Por 1.000 peticiones con éxito | E9: CONFIGURADA | F9: 0 | G9: 5 | H9: 30 | I9: ~US$ 1,5-3 por 1.000 peticiones con éxito; hay franja gratuita mensual. Solo se paga lo que responde bien. El volumen depende de cuántas tiendas bloqueen: hoy es impredecible.
A10: USDA FoodData Central | B10: 990 productos Branded del snapshot (818 tras dedup) | C10: Gratuito con API key | D10: Sin coste | E10: CONFIGURADA | F10: 0 | G10: 0 | H10: 0 | I10: Gratuito. Solo exige registrar una clave y respetar el límite de peticiones por hora.
A11: Open Food Facts | B11: 28.236 productos del snapshot y, en adelante, la base MongoDB entera | C11: Gratuito · ODbL | D11: Sin coste | E11: Sin clave: descarga pública | F11: 0 | G11: 0 | H11: 0 | I11: Licencia ODbL: es gratis y se puede usar comercialmente, pero OBLIGA a atribuir y a compartir con la misma licencia las bases derivadas. Ponerlo en el informe y en el pie de la SPA.
A12: eCFR (Title 21) y DIGESA | B12: Corpus regulatorio: 702 + 32 documentos | C12: Gratuito | D12: Sin coste | E12: Sin clave: API y PDF públicos | F12: 0 | G12: 0 | H12: 0 | I12: DIGESA devuelve 403 si se piden páginas seguidas: la ingesta ya lo espacia.
A13: Dominio y DNS | B13: Nombre público de la aplicación y certificado TLS | C13: Registro anual | D13: Anual | E13: Por contratar | F13: 1 | G13: 1.5 | H13: 3 | I13: US$ 12-35 al año según extensión. El certificado es gratuito (Huawei SCM o Let's Encrypt).
A14: MongoDB Atlas | B14: Alternativa gestionada a DDS para Open Food Facts | C14: NO CONTRATADO | D14: Por hora | E14: — | F14: 0 | G14: 0 | H14: 0 | I14: Se evalúa en la hoja MongoDB-OFF como opción C. Vive fuera de Huawei: suma latencia entre nubes y tráfico de salida que hoy no se paga.
A15: Redis / DCS | B15: Cache de búsquedas (opcional en el MVP, requerido en S10) | C15: NO CONTRATADO | D15: Por hora | E15: REDIS_URL apunta a localhost | F15: 0 | G15: 0 | H15: 0 | I15: Hoy no existe en la nube. El cache de LLM va sobre Postgres, no sobre Redis. Entra solo si S10 lo exige.
A17: TOTAL SUSCRIPCIONES (US$/mes) | F17: =SUM(F5:F15)-F5-F6 | G17: =SUM(G5:G15)-G5-G6 | H17: =SUM(H5:H15)-H5-H6 | I17: Excluye MaaS y la infraestructura de Huawei porque se suman aparte en el Resumen: aquí quedan solo las suscripciones de terceros.
A19: Lo que hay que decidir sobre las suscripciones
A20: 1. Supabase y RDS están pagándose a la vez en cuanto se despliegue. La decisión de INFRA-HUAWEI-CLOUD.md §1 es que Supabase sale, pero la migración son 13,5-15 h de código todavía sin hacer. Hasta que se haga, o se paga doble o el despliegue en Huawei apunta a Supabase por internet, que es justo lo que la decisión quería evitar.
A21: 2. Tavily y Bright Data son los dos únicos gastos que no se pueden acotar por adelantado. El resto del libro es capacidad reservada o consumo con kill-switch; estos dos son por petición y dependen de cuántas tiendas bloqueen. Recomendación: fijar un tope de gasto en el panel de cada proveedor antes de que el agente N3 corra sin supervisión.
A22: 3. La licencia de Open Food Facts es ODbL y no es decorativa. Obliga a atribuir la fuente y a publicar bajo la misma licencia cualquier base derivada que se distribuya. Usarla internamente y mostrar resultados no es problema; venderla como base de datos propia sí lo es. Conviene resolverlo con el CITE antes del contrato, no después.

Sheet Infraestructura
A1: Infraestructura Huawei Cloud que hace falta
A2: Región LA-Santiago. Columnas G, H, I son celdas de entrada: pegue ahí el precio del calculador y todo se recalcula.
A4: Categoría | B4: Concepto | C4: Especificación | D4: Unidad | E4: Cant. | F4: Uso/mes | G4: P. mín | H4: P. esp. | I4: P. máx | J4: Coste mín | K4: Coste esp. | L4: Coste máx | M4: Confianza | N4: Por qué está y cómo verificar el precio
A5: Cómputo | B5: ECS s7n.xlarge.2 | C5: 4 vCPU · 8 GB · Ubuntu 22.04 · API + nginx + SPA | D5: US$/hora | E5: 1 | F5: =Parametros!$B$6 | G5: 0.096 | H5: 0.125 | I5: 0.15 | J5: =$E5*$F5*G5 | K5: =$E5*$F5*H5 | L5: =$E5*$F5*I5 | M5: Media | N5: Los 8 GB los exige bge-m3: 2,3 GB de pesos y 3,5-4,5 GB de proceso. Sin GPU: el gate P03 se midió en CPU con p95 176 ms contra un techo de 2 s. Calculator → ECS → LA-Santiago → s7n → 4 vCPU/8 GB → Pay-per-use.
A6: Cómputo | B6: Disco de sistema | C6: EVS SSD 40 GB | D6: US$/GB-mes | E6: 40 | F6: 1 | G6: 0.1 | H6: 0.12 | I6: 0.15 | J6: =$E6*$F6*G6 | K6: =$E6*$F6*H6 | L6: =$E6*$F6*I6 | M6: Media | N6: La imagen Docker con PyTorch CPU pesa ~1,5 GB. Calculator → EVS → General Purpose SSD.
A7: Base de datos | B7: RDS PostgreSQL 16 | C7: rds.pg.n1.large.2 · 2 vCPU/4 GB · nodo único · sin acceso público | D7: US$/hora | E7: 1 | F7: =Parametros!$B$6 | G7: 0.07 | H7: 0.095 | I7: 0.12 | J7: =$E7*$F7*G7 | K7: =$E7*$F7*H7 | L7: =$E7*$F7*I7 | M7: Media | N7: Estado de aplicación, cache_llm, perfiles y usuarios. La opción primario/en espera DUPLICA esta línea y se difiere a producción. Calculator → RDS → PostgreSQL → Single.
A8: Base de datos | B8: Almacenamiento RDS | C8: SSD 40 GB (mínimo del servicio) | D8: US$/GB-mes | E8: 40 | F8: 1 | G8: 0.15 | H8: 0.18 | I8: 0.22 | J8: =$E8*$F8*G8 | K8: =$E8*$F8*H8 | L8: =$E8*$F8*I8 | M8: Media | N8: Con entrada_json/salida_json en jsonb, 40 GB dan para años: el crecimiento medido es ~0,12 MB por consulta premium.
A9: Base de datos | B9: Backup automático + PITR | C9: Retención 7 días | D9: US$/mes | E9: 1 | F9: 1 | G9: 0 | H9: 0 | I9: 3 | J9: =$E9*$F9*G9 | K9: =$E9*$F9*H9 | L9: =$E9*$F9*I9 | M9: Baja | N9: Huawei suele incluir sin cargo un backup del tamaño contratado; el exceso se cobra. CONFIRMAR en el calculador.
A10: Almacenamiento | B10: EVS de datos | C10: SSD 100 GB en /data: índice LanceDB 135 MB + snapshot 66 MB + PDFs | D10: US$/GB-mes | E10: 100 | F10: 1 | G10: 0.1 | H10: 0.12 | I10: 0.15 | J10: =$E10*$F10*G10 | K10: =$E10*$F10*H10 | L10: =$E10*$F10*I10 | M10: Media | N10: 201 MB ocupados hoy. Los 100 GB son margen para el snapshot siguiente y los PDFs, que crecen sin poda.
A11: Almacenamiento | B11: OBS Standard | C11: PDFs + snapshot + pesos de bge-m3 (~20 GB) | D11: US$/GB-mes | E11: 20 | F11: 1 | G11: 0.019 | H11: 0.024 | I11: 0.03 | J11: =$E11*$F11*G11 | K11: =$E11*$F11*H11 | L11: =$E11*$F11*I11 | M11: Media | N11: Fuente de verdad con versionado activado: reconstruir el nodo son tres obsutil sync, no un reindexado de horas.
A12: Almacenamiento | B12: OBS peticiones y salida | C12: Volumen bajo: demo y sincronización del nodo | D12: US$/mes | E12: 1 | F12: 1 | G12: 0.5 | H12: 1 | I12: 2 | J12: =$E12*$F12*G12 | K12: =$E12*$F12*H12 | L12: =$E12*$F12*I12 | M12: Baja | N12: Se cobra por cada 10.000 peticiones y por tráfico saliente. Es una de las dos líneas con confianza baja del libro.
A13: Almacenamiento | B13: CBR — respaldo del disco | C13: Copia diaria de /data, retención 7 días | D13: US$/GB-mes | E13: 100 | F13: 1 | G13: 0.05 | H13: 0.06 | I13: 0.08 | J13: =$E13*$F13*G13 | K13: =$E13*$F13*H13 | L13: =$E13*$F13*I13 | M13: Media | N13: Con el backup de RDS cubre el RPO ≤ 24 h / RTO ≤ 4 h del ADR-003. Probar una restauración antes del CDR.
A14: Red | B14: EIP — cargo por IP | C14: 1 IP elástica asociada al ECS | D14: US$/hora | E14: 1 | F14: =Parametros!$B$6 | G14: 0.005 | H14: 0.007 | I14: 0.01 | J14: =$E14*$F14*G14 | K14: =$E14*$F14*H14 | L14: =$E14*$F14*I14 | M14: Media | N14: El cargo por IP es aparte del tráfico. Calculator → EIP → Pay-per-use por tráfico.
A15: Red | B15: Tráfico saliente | C15: SPA, API y descarga de PDFs | D15: US$/GB | E15: 1 | F15: =Parametros!$B$14 | G15: 0.08 | H15: 0.09 | I15: 0.12 | J15: =$E15*$F15*G15 | K15: =$E15*$F15*H15 | L15: =$E15*$F15*I15 | M15: Media | N15: El tráfico ENTRANTE no se cobra: descargar 15,4 GiB de Open Food Facts cada mes es gratis. Solo se paga la salida.
A16: Operación | B16: LTS — logs | C16: nginx + contenedor, ~2 GB/mes, retención 7 días | D16: US$/GB | E16: 1 | F16: 2 | G16: 0.3 | H16: 0.4 | I16: 0.5 | J16: =$E16*$F16*G16 | K16: =$E16*$F16*H16 | L16: =$E16*$F16*I16 | M16: Baja | N16: Suele haber cuota gratuita mensual de ingesta: comprobarla antes de presupuestar.
A17: Operación | B17: CES + SMN — alarmas | C17: 5 alarmas con aviso por correo | D17: US$/mes | E17: 1 | F17: 1 | G17: 0 | H17: 0 | I17: 1 | J17: =$E17*$F17*G17 | K17: =$E17*$F17*H17 | L17: =$E17*$F17*I17 | M17: Media | N17: CPU, memoria (el recurso escaso), disco de /data, instancia caída y conexiones de RDS.
A18: Operación | B18: DAS — consola SQL | C18: Acceso a RDS desde el navegador | D18: US$/mes | E18: 1 | F18: 1 | G18: 0 | H18: 0 | I18: 0 | J18: =$E18*$F18*G18 | K18: =$E18*$F18*H18 | L18: =$E18*$F18*I18 | M18: Media | N18: La edición estándar es gratuita. Sustituye al SQL Editor de Supabase.
A19: Operación | B19: SCM — certificado TLS | C19: Certificado de dominio único | D19: US$/mes | E19: 1 | F19: 1 | G19: 0 | H19: 0 | I19: 0 | J19: =$E19*$F19*G19 | K19: =$E19*$F19*H19 | L19: =$E19*$F19*I19 | M19: Media | N19: Hay certificado gratuito. Alternativa sin coste: Let's Encrypt en el propio nginx.
A20: Operación | B20: DNS — zona pública | C20: 1 zona alojada | D20: US$/mes | E20: 1 | F20: 1 | G20: 0.5 | H20: 0.5 | I20: 0.5 | J20: =$E20*$F20*G20 | K20: =$E20*$F20*H20 | L20: =$E20*$F20*I20 | M20: Media | N20: No incluye el registro del dominio, que va en la hoja Suscripciones.
A21: Ingesta | B21: ECS con GPU por horas | C21: 1 h por trimestre para reindexar con bge-m3 | D21: US$/mes | E21: 1 | F21: 1 | G21: 0.5 | H21: 0.7 | I21: 1.5 | J21: =$E21*$F21*G21 | K21: =$E21*$F21*H21 | L21: =$E21*$F21*I21 | M21: Baja | N21: MEDIDO: 15-30 min con GPU contra 2-3 h en CPU para 29.054 productos. Encender una instancia con GPU una hora por trimestre cuesta ~US$ 8 al año y saca la ingesta del portátil, que hoy es la única pieza fuera de la nube.
A23: SUBTOTALES POR CATEGORÍA
B24: Cómputo | J24: =SUMIF($A$5:$A$21,$B24,J$5:J$21) | K24: =SUMIF($A$5:$A$21,$B24,K$5:K$21) | L24: =SUMIF($A$5:$A$21,$B24,L$5:L$21)
B25: Base de datos | J25: =SUMIF($A$5:$A$21,$B25,J$5:J$21) | K25: =SUMIF($A$5:$A$21,$B25,K$5:K$21) | L25: =SUMIF($A$5:$A$21,$B25,L$5:L$21)
B26: Almacenamiento | J26: =SUMIF($A$5:$A$21,$B26,J$5:J$21) | K26: =SUMIF($A$5:$A$21,$B26,K$5:K$21) | L26: =SUMIF($A$5:$A$21,$B26,L$5:L$21)
B27: Red | J27: =SUMIF($A$5:$A$21,$B27,J$5:J$21) | K27: =SUMIF($A$5:$A$21,$B27,K$5:K$21) | L27: =SUMIF($A$5:$A$21,$B27,L$5:L$21)
B28: Operación | J28: =SUMIF($A$5:$A$21,$B28,J$5:J$21) | K28: =SUMIF($A$5:$A$21,$B28,K$5:K$21) | L28: =SUMIF($A$5:$A$21,$B28,L$5:L$21)
B29: Ingesta | J29: =SUMIF($A$5:$A$21,$B29,J$5:J$21) | K29: =SUMIF($A$5:$A$21,$B29,K$5:K$21) | L29: =SUMIF($A$5:$A$21,$B29,L$5:L$21)
B31: TOTAL INFRAESTRUCTURA (mes, sin MongoDB) | J31: =SUM(J24:J29) | K31: =SUM(K24:K29) | L31: =SUM(L24:L29)
B32: + MongoDB para Open Food Facts (opción elegida) | J32: ='MongoDB-OFF'!$D$89 | K32: ='MongoDB-OFF'!$E$89 | L32: ='MongoDB-OFF'!$F$89
B33: TOTAL CON MongoDB (mes) | J33: =J31+J32 | K33: =K31+K32 | L33: =L31+L32
A35: Lo que deliberadamente NO se contrata, y qué lo dispararía
A36: Servicio | B36: Por qué no ahora | N36: Disparador que lo haría entrar
A37: CCE / CCI (Kubernetes) | B37: Un contenedor no necesita un orquestador: es operación sin un cuello que resolver. | N37: Nunca, mientras sea una imagen y una instancia.
A38: ELB (balanceador) | B38: Una sola instancia no balancea nada. | N38: Cuando haya 2 réplicas de la API, es decir, cuando la p95 o la CPU se sostengan altas.
A39: FunctionGraph (serverless) | B39: 2,3 GB de modelo no caben en un arranque en frío. | N39: Nunca para la API. Sí para tareas cortas del ETL.
A40: DCS / Redis | B40: La cola va sobre Postgres (ADR-003) y el cache de LLM también. | N40: S10, si el cache de búsquedas deja de caber en proceso.
A41: WAF y CDN | B41: Tráfico de demo, usuarios todos en Perú. | N41: Servicio institucional expuesto a internet con datos de terceros.
A42: NAT Gateway | B42: El agente web no está en el MVP. | N42: Fase F4: el agente necesita IP fija para identificarse ante las tiendas y respetar rate-limits.
A43: RDS en alta disponibilidad | B43: Duplica el precio de la base y el MVP tolera una ventana de restauración. | N43: Cuando el MVP pase a servicio real con compromiso de disponibilidad.

Sheet MongoDB-OFF
A1: MongoDB para Open Food Facts — dimensionado
A2: Todas las cifras del bloque A y B están MEDIDAS contra world.openfoodfacts.org/data el 2026-08-14. Nada aquí es una analogía con otro proyecto.
A4: A · LO QUE OPEN FOOD FACTS PUBLICA HOY (medido por HTTP el 2026-08-14)
B5: Recurso | C5: Formato | D5: Bytes | E5: GiB | F5: GB (decimal) | I5: Cómo se midió
B6: Productos en la base | C6: — | D6: 4680925 | I6: API v2: /api/v2/search?page_size=1 devuelve "count":4680925. Es el universo entero, no una muestra.
B7: Volcado MongoDB (openfoodfacts-mongodbdump.gz) | C7: BSON comprimido | D7: 15429978249 | E7: =D7/1024^3 | F7: =D7/10^9 | I7: HEAD sobre static.openfoodfacts.org. Last-Modified: 2026-08-14 06:20 UTC. Se regenera cada noche.
B8: Export JSONL (openfoodfacts-products.jsonl.gz) | C8: JSON por línea, gzip | D8: 12672091473 | E8: =D8/1024^3 | F8: =D8/10^9 | I8: HEAD, misma fecha. Un objeto JSON por línea; es lo que conviene si se va a proyectar al importar.
B9: Export CSV (en.openfoodfacts.org.products.csv.gz) | C9: TSV comprimido | D9: 1275171186 | E9: =D9/1024^3 | F9: =D9/10^9 | I9: HEAD, 2026-08-14 11:43 UTC. Es el que usa hoy etl/cargar_off_bulk.py. Trae un subconjunto plano de campos: NO sirve para MongoDB.
B10: Delta diario (1 de los 14 disponibles) | C10: JSONL comprimido | D10: 23825449 | E10: =D10/1024^3 | F10: =D10/10^9 | I10: openfoodfacts_products_1786342032_1786428017.json.gz. OFF mantiene los 14 últimos días.
A12: B · ANATOMÍA DEL DOCUMENTO (medido descomprimiendo un delta real: 6.487 documentos)
B13: Medida | D13: Valor | E13: Unidad | I13: Qué significa
B14: Documentos en el delta analizado | D14: 6487 | E14: docs | I14: Productos creados o modificados en 24 h. Es también la tasa de cambio diaria de la base.
B15: Bytes sin comprimir del delta | D15: 142934814 | E15: bytes | I15: 136,3 MB. Descomprimido y contado línea a línea.
B16: Ratio de compresión gzip | D16: =D15/D10 | E16: × | I16: Seis a uno. Este número es la clave para pasar de los tamaños publicados al tamaño real en disco.
B17: Documento medio (JSON) | D17: 23906 | E17: bytes | I17: 23,3 KiB. Un producto de OFF NO es un registro pequeño.
B18: Documento mediano (JSON) | D18: 15802 | E18: bytes | I18: La distribución tiene cola larga: la media es 1,5× la mediana.
B19: Percentil 95 | D19: 50215 | E19: bytes | I19: Uno de cada veinte productos pasa de 49 KiB.
B20: Documento más grande del delta | D20: 446123 | E20: bytes | I20: 436 KiB. Lejos del límite de 16 MB de BSON, así que no hay riesgo de rechazo.
B21: Documento medio (BSON) | D21: 24044 | E21: bytes | I21: Codificado con bson.BSON.encode: BSON pesa prácticamente lo mismo que el JSON. No hay ahorro por el formato.
B22: Claves distintas de primer nivel | D22: 1066 | E22: campos | I22: MIL SESENTA Y SEIS campos distintos en 6.487 documentos. El esquema de OFF es abierto: cada contribuidor y cada robot añaden los suyos.
B23: ingredients_text presente en | D23: 0.402 | E23: % | I23: Solo el 40 % de los productos trae la lista de ingredientes — que es justo el campo sobre el que AgroScout busca.
A25: C · DEL VOLCADO PUBLICADO AL TAMAÑO REAL EN DISCO
B26: Paso del cálculo | D26: Valor | E26: Unidad | I26: De dónde sale
B27: Bytes comprimidos por documento — delta | D27: =D10/D14 | E27: bytes/doc | I27: El delta trae productos recién modificados, que son los más completos: es una muestra SESGADA hacia arriba.
B28: Bytes comprimidos por documento — población | D28: =D8/D6 | E28: bytes/doc | I28: El export JSONL entero dividido entre los 4,68 M de productos. Esta sí es la población completa.
B29: Factor de sesgo del delta | D29: =D27/D28 | E29: × | I29: Cuánto más grande es un documento recién tocado que el producto medio. Sale 1,36.
B30: DOCUMENTO MEDIO DE LA POBLACIÓN | D30: =D17/D29 | E30: bytes | I30: El documento medio del delta corregido por el sesgo: ~17,6 KB. Es la cifra que manda en todo lo que sigue.
B31: Colección sin comprimir (BSON) | D31: =D6*D30/10^9 | E31: GB | I31: 4.680.925 × 17,6 KB. Contraste independiente: el JSONL descomprimido son 11,8 GiB × 6,0 = 71 GiB, y el volcado BSON es 1,22× el JSONL, o sea ~86 GiB. El cálculo cae dentro del contraste.
B32: Factor de compresión de WiredTiger | D32: 3 | E32: × | I32: CELDA DE ENTRADA. snappy —el compresor de bloque por defecto— rinde ~3× sobre este tipo de dato; zstd y zlib llegan a 4-4,5× a cambio de CPU y se activan por colección. La referencia de arriba: gzip logra 6× sobre este mismo dato, y ningún compresor de bloque llega ahí porque comprime por páginas, no por fichero.
B33: COLECCIÓN EN DISCO | D33: =D31/D32 | E33: GB | I33: Lo que ocupa de verdad la colección en el volumen. Con zstd baja a ~19 GB; ponga 4,5 en la celda de arriba para verlo.
A35: D · ÍNDICES (cardinalidad de los arrays MEDIDA sobre el mismo delta)
B36: Índice | C36: Tipo | D36: Entradas/doc | E36: Presencia | F36: Entradas totales | G36: GB | I36: Para qué sirve en AgroScout
B37: Bytes por entrada de índice | D37: 50 | E37: bytes | I37: CELDA DE ENTRADA. Clave más RecordId tras compresión de prefijos. 45-60 es el rango razonable para claves de texto cortas.
B38: _id (code) | C38: único | D38: 1 | E38: 1 | F38: =$D$6*D38*E38 | G38: =F38*$D$37/10^9 | I38: Obligatorio. El código de barras como clave primaria.
B39: countries_tags | C39: multiclave | D39: 1.2 | E39: 1 | F39: =$D$6*D39*E39 | G39: =F39*$D$37/10^9 | I39: Filtrar por mercado. Es EL índice del mapa comercial: sin él, cada consulta por país recorre 4,68 M de documentos.
B40: categories_tags | C40: multiclave | D40: 6.5 | E40: 0.467 | F40: =$D$6*D40*E40 | G40: =F40*$D$37/10^9 | I40: Filtrar por categoría de producto. Presente solo en el 47 % de los documentos.
B41: ingredients_tags | C41: multiclave | D41: 25.3 | E41: 0.402 | F41: =$D$6*D41*E41 | G41: =F41*$D$37/10^9 | I41: EL ÍNDICE CARO: 25 etiquetas por documento. Es también el que hace posible la búsqueda por insumo sin recorrer la colección.
B42: labels_tags | C42: multiclave | D42: 2.1 | E42: 0.32 | F42: =$D$6*D42*E42 | G42: =F42*$D$37/10^9 | I42: Orgánico, sin gluten, comercio justo: los reclamos que interesan al CITE.
B43: additives_tags | C43: multiclave | D43: 2.3 | E43: 0.402 | F43: =$D$6*D43*E43 | G43: =F43*$D$37/10^9 | I43: Aditivos. Alimenta el análisis regulatorio que ya existe en el proyecto.
B44: last_modified_t | C44: simple | D44: 1 | E44: 1 | F44: =$D$6*D44*E44 | G44: =F44*$D$37/10^9 | I44: Refresco incremental: traer solo lo que cambió desde el último delta.
...

Sheet Precios-Huawei
A1: Precios de referencia de Huawei Cloud
A2: Advertencia importante: Huawei NO publica una lista de precios en HTML. Cada cifra de aquí es una estimación con rango, y abajo está cómo verificarla.
A4: Servicio | B4: Especificación | C4: P. mín | D4: P. esp. | E4: P. máx | F4: Unidad | G4: Cómo verificarlo en minutos
A5: ECS s7n.xlarge.2 | B5: 4 vCPU · 8 GB · General computing-plus | C5: 0.096 | D5: 0.125 | E5: 0.15 | F5: US$/hora | G5: calculator.html → ECS → LA-Santiago → General computing-plus s7n → 4 vCPU/8 GB → Pay-per-use. Anote también el precio Yearly para el parámetro de descuento.
A6: ECS s7n.2xlarge.4 | B6: 8 vCPU · 32 GB — nodo de MongoDB, opción B | C6: 0.38 | D6: 0.5 | E6: 0.62 | F6: US$/hora | G6: Mismo asistente, cambiando el flavor. Escala aproximadamente con vCPU × ratio de memoria.
A7: RDS for PostgreSQL | B7: rds.pg.n1.large.2 · 2 vCPU/4 GB · nodo único | C7: 0.07 | D7: 0.095 | E7: 0.12 | F7: US$/hora | G7: calculator → RDS → PostgreSQL → Single → 2 vCPU/4 GB. La opción Primary/Standby DUPLICA el importe.
A8: DDS conjunto de réplicas | B8: dds.mongodb.s6.xlarge.4.repset · 4 vCPU/16 GB · POR NODO | C8: 0.28 | D8: 0.4 | E8: 0.53 | F8: US$/hora | G8: calculator → DDS → Replica set → 3 nodos. RECUERDE: el nodo único se retiró el 15-jul-2023, así que la cantidad mínima es 3 y hay que multiplicar.
A9: EVS General Purpose SSD | B9: Volumen de datos | C9: 0.1 | D9: 0.12 | E9: 0.15 | F9: US$/GB-mes | G9: calculator → EVS → General Purpose SSD. Se factura por capacidad aprovisionada, no por uso.
A10: Almacenamiento de RDS / DDS | B10: SSD en la nube | C10: 0.15 | D10: 0.18 | E10: 0.22 | F10: US$/GB-mes | G10: Va dentro del asistente de la base, apartado Storage. Es más caro que el EVS suelto.
A11: OBS Standard | B11: Almacenamiento de objetos | C11: 0.019 | D11: 0.024 | E11: 0.03 | F11: US$/GB-mes | G11: calculator → OBS → Standard storage → LA-Santiago. Las peticiones y la salida se cobran aparte.
A12: CBR | B12: Bóveda de respaldo | C12: 0.05 | D12: 0.06 | E12: 0.08 | F12: US$/GB-mes | G12: calculator → CBR → Cloud Server Backup, por capacidad de bóveda.
A13: EIP — cargo por IP | B13: IP elástica asociada | C13: 0.005 | D13: 0.007 | E13: 0.01 | F13: US$/hora | G13: calculator → EIP → Pay-per-use. El cargo por la IP y el del tráfico son dos líneas distintas.
A14: Tráfico saliente a internet | B14: Egress | C14: 0.08 | D14: 0.09 | E14: 0.12 | F14: US$/GB | G14: El tráfico ENTRANTE no se cobra. Ese es el motivo de que descargar 15,4 GiB de Open Food Facts cada noche salga gratis.
A15: LTS — ingesta de logs | B15: Retención 7 días | C15: 0.3 | D15: 0.4 | E15: 0.5 | F15: US$/GB | G15: Suele haber cuota gratuita mensual: compruébela antes de presupuestar. Confianza BAJA.
A16: DNS — zona pública | B16: 1 zona alojada | C16: 0.5 | D16: 0.5 | E16: 0.5 | F16: US$/mes | G16: Coste bajo y estable. No incluye el registro del dominio.
A17: CES + SMN, DAS, SCM | B17: Alarmas, consola SQL, certificado | C17: 0 | D17: 0 | E17: 1 | F17: US$/mes | G17: La monitorización básica de CES, el correo de SMN, la edición estándar de DAS y el certificado gratuito de SCM no se cobran en estos volúmenes.
A19: Por qué estos precios son entradas y no hechos
A20: Huawei Cloud no publica sus tarifas en una página legible: viven dentro del calculador (huaweicloud.com/intl/en-us/pricing/calculator.html), que es una aplicación JavaScript, no citable ni automatizable. La documentación de facturación explica los MODOS de cobro, no los importes. Por eso este libro no afirma tener los precios oficiales.
A21: Lo que hace en su lugar es mejor para un presupuesto que se va a presentar: cada precio es una celda amarilla con su rango mínimo/esperado/máximo, y todo lo demás son fórmulas. En cuanto usted pegue los números del calculador con la región LA-Santiago puesta, el Resumen, los Escenarios y las hojas de detalle se recalculan solos, sin tocar una fórmula.
A22: Las dos líneas con menos confianza son las peticiones de OBS y la ingesta de LTS: en volúmenes de demo son céntimos, pero con uso real conviene medir un mes antes de comprometer una cifra anual.
A23: Lo que este presupuesto NO incluye: registro y renovación del dominio, horas de desarrollo e implantación, soporte de pago de Huawei (el plan Basic es gratuito) e impuestos locales si el contrato se firma con un socio peruano — para eso está el parámetro de impuestos.

Sheet Escenarios
A1: Escenarios de operación
A2: El mismo diseño en tres regímenes. Lo que cambia son las horas encendido y el volumen de consultas, no la arquitectura.
A4: Concepto | B4: A · Demo y ensayos | C4: B · MVP 24×7 | D4: C · Piloto con el CITE | E4: Qué cambia
A5: Runs premium al mes | B5: 20 | C5: =Parametros!$B$11 | D5: 500 | E5: A: ensayos del equipo antes del CDR. C: uso real de varias organizaciones.
A6: Runs gratuitos al mes | B6: 0 | C6: =Parametros!$B$12 | D6: 2000 | E6: El plan gratuito corta antes de las etapas 4 y 5, pero NO es gratis: US$ 0,104 por run.
A7: Costo de IA | B7: =B5*'Costos-IA'!$H$22 | C7: ='Costos-IA'!$E$32 | D7: =(D5*'Costos-IA'!$H$22+D6*'Costos-IA'!$H$21)*(1-Parametros!$B$13) | E7: En A no hay cache que ayude: cada ensayo es una consulta distinta.
A8: Infraestructura Huawei | B8: =Infraestructura!$K$31-(Infraestructura!$K$5+Infraestructura!$K$7)*(1-Parametros!$B$7/Parametros!$B$6) | C8: =Infraestructura!$K$31 | D8: =Infraestructura!$K$31*1.9 | E8: A: ECS y RDS encendidos 80 h/mes; el almacenamiento, la EIP y los backups se pagan igual. C: aproximación por factor — para costearlo línea por línea hay que abrir la hoja Infraestructura y subir cantidades.
A9: MongoDB (opción elegida) | B9: 0 | C9: ='MongoDB-OFF'!$E$89 | D9: ='MongoDB-OFF'!$E$89 | E9: En A no hace falta: el snapshot filtrado de 29.054 productos ya está en disco.
A10: Suscripciones de terceros | B10: =Suscripciones!$G$17*0.3 | C10: =Suscripciones!$G$17 | D10: =Suscripciones!$G$17*2 | E10: En A casi todo sigue en plan gratuito. En C, Tavily y Bright Data empiezan a consumir de verdad.
A12: SUBTOTAL MENSUAL (US$) | B12: =SUM(B7:B10) | C12: =SUM(C7:C10) | D12: =SUM(D7:D10)
A13: Impuestos | B13: =B12*Parametros!$B$9 | C13: =C12*Parametros!$B$9 | D13: =D12*Parametros!$B$9 | E13: 0 % con facturación directa a Huawei Cloud International; 18 % de IGV vía socio peruano.
A14: TOTAL MENSUAL (US$) | B14: =B12+B13 | C14: =C12+C13 | D14: =D12+D13
A15: TOTAL MENSUAL (S/) | B15: =B14*Parametros!$B$8 | C15: =C14*Parametros!$B$8 | D15: =D14*Parametros!$B$8
A16: TOTAL ANUAL (US$) | B16: =B14*12 | C16: =C14*12 | D16: =D14*12
A17: TOTAL ANUAL con compromiso (US$) | B17: =B14*12*(1-Parametros!$B$10) | C17: =C14*12*(1-Parametros!$B$10) | D17: =D14*12*(1-Parametros!$B$10)
A18: Costo por consulta (todo incluido) | B18: =B14/MAX(B5+B6,1) | C18: =C14/MAX(C5+C6,1) | D18: =D14/MAX(D5+D6,1) | E18: Infraestructura incluida, no solo el LLM. Baja rápido con la escala porque el grueso de la factura es fijo.
A20: Cuándo aplica cada escenario
A21: A · Demo y ensayos — hasta el CDR del 28 de agosto. Encender ECS y RDS solo para ensayar y presentar, y no desplegar MongoDB todavía: el snapshot filtrado ya está en disco y responde. Es el escenario correcto para las próximas semanas y el más barato con diferencia.
A22: B · MVP 24×7 — el CITE empieza a usarlo y el servicio debe estar disponible. Es la arquitectura de INFRA-HUAWEI-CLOUD.md más la instancia de MongoDB con la proyección de Open Food Facts.
A23: C · Piloto con el CITE — varias organizaciones consultando de verdad. Aquí el número que hay que vigilar no es la infraestructura: es el kill-switch de US$ 10/mes, que con 500 runs premium se agota el primer día. Subirlo es una decisión consciente y cuesta lo que dice la hoja Costos-IA.
A24: ATENCIÓN · La columna C es una aproximación por factor sobre la infraestructura, no un costeo línea por línea. Antes de llevarla a una propuesta firmada hay que abrir la hoja Infraestructura y subir cantidades una a una: la alta disponibilidad de la base, el balanceador y el WAF son tres líneas que ningún factor multiplicativo estima bien.

Sheet Parametros
A1: Parámetros globales
A2: Cambie aquí y todo el libro se recalcula
A4: Parámetro | B4: Valor | C4: Unidad | D4: Nota
A5: Región | B5: LA-Santiago | C5: — | D5: La región de Huawei Cloud más cercana a Perú (~40-60 ms desde Lima). Exige cuenta Huawei Cloud INTERNATIONAL, no la del sitio de China continental.
A6: Horas por mes (24×7) | B6: 730 | C6: h | D6: Convención de facturación en la nube: 365×24/12 = 730.
A7: Horas/mes escenario demo | B7: 80 | C7: h | D7: ECS y bases encendidos solo para ensayos y la demo del CDR. El almacenamiento se paga igual.
A8: Tipo de cambio USD → PEN | B8: 3.75 | C8: S/ por US$ | D8: EDITAR con el tipo de cambio del día de la presentación.
A9: Impuestos aplicables | B9: 0 | C9: % | D9: 0 % si se factura directo con Huawei Cloud International. Vía socio peruano: 18 % de IGV.
A10: Descuento por compromiso anual | B10: 0.35 | C10: % | D10: Prepago anual de ECS, RDS y DDS. VERIFICAR el descuento real en el calculador; 30-40 % es lo habitual.
A11: Runs premium por mes | B11: 100 | C11: runs | D11: Consulta completa: 5 etapas de LLM. Es el volumen que manda sobre la factura de IA.
A12: Runs gratuitos por mes | B12: 200 | C12: runs | D12: El paywall corta antes de las etapas 4 y 5. OJO: no son gratis, son US$ 0,104 cada uno.
A13: Tasa de acierto del cache | B13: 0.514 | C13: % | D13: MEDIDO: 109 aciertos sobre 212 filas de etapa con modelo en etapas_ejecucion. El cache es por (entrada, modelo, etapa, snapshot).
A14: Tráfico saliente mensual | B14: 30 | C14: GB | D14: SPA (173 KB), PDFs (~26 KB c/u) y API. Conservador para demo y piloto.

Sheet Leeme
A1: Cómo usar este libro
A2: AgroScout IA · CITEagroindustrial Chavimochic · elaborado el 2026-08-14
B5: QUÉ CONTIENE Y EN QUÉ ORDEN LEERLO
B6: Resumen — la cifra que se presenta, con las cuatro piezas que la componen.
B7: Costos-IA — el consumo de ModelArts MaaS etapa por etapa. Es el bloque MEDIDO del libro.
B8: Suscripciones — lo que hoy está contratado o con clave activa, y qué habría que decidir sobre cada cosa.
B9: Infraestructura — las 17 líneas de Huawei Cloud que hacen falta, con precio mínimo/esperado/máximo.
B10: MongoDB-OFF — el dimensionado de Open Food Facts, medido contra la fuente real, y las cinco opciones de despliegue.
B11: Precios-Huawei — la tabla de precios unitarios y cómo verificar cada uno en el calculador.
B12: Escenarios — demo, MVP 24×7 y piloto.
B13: Parametros — los diez números que mueven todo el libro.
B15: CÓMO ACTUALIZARLO
B16: 1. Abra Parametros y ajuste tipo de cambio, horas al mes, volúmenes de consulta e impuestos.
B17: 2. Abra el calculador de Huawei con la región LA-Santiago puesta y pegue los precios en las celdas amarillas de Precios-Huawei e Infraestructura.
... B38: Tampoco incluye las 13,5-15 horas de código que cuesta migrar de Supabase a RDS, que están medidas en INFRA-HUAWEI-CLOUD.md §13 pero son esfuerzo, no factura.
