Workbook

Sheet Resumen
A1: Resumen ejecutivo — presupuesto de infraestructura
A2: AgroScout IA · CITEagroindustrial Chavimochic · Huawei Cloud LA-Santiago · 2026-08-02
A4: Bloque | B4: Mínimo (US$) | C4: Esperado (US$) | D4: Máximo (US$) | E4: Comentario
A5: Cómputo (ECS + disco de sistema) | B5: =Detalle!J24 | C5: =Detalle!K24 | D5: =Detalle!L24 | E5: 1 instancia de 4 vCPU/8 GB. Los 8 GB los exige bge-m3, no el tráfico.
A6: Base de datos (RDS PostgreSQL) | B6: =Detalle!J25 | C6: =Detalle!K25 | D6: =Detalle!L25 | E6: Nodo único, sin acceso público. La alta disponibilidad duplica esta línea.
A7: Almacenamiento (EVS + OBS + CBR) | B7: =Detalle!J26 | C7: =Detalle!K26 | D7: =Detalle!L26 | E7: 100 GB de datos, 20 GB en OBS y respaldo diario.
A8: Red (EIP + tráfico) | B8: =Detalle!J27 | C8: =Detalle!K27 | D8: =Detalle!L27 | E8: Pago por tráfico: la demo mueve megabytes, no gigabytes.
A9: Operación (LTS, CES, DNS, SCM) | B9: =Detalle!J28 | C9: =Detalle!K28 | D9: =Detalle!L28 | E9: Casi todo gratuito en estos volúmenes.
A10: Subtotal infraestructura | B10: =Detalle!J30 | C10: =Detalle!K30 | D10: =Detalle!L30
A11: LLM · ModelArts MaaS | B11: ='LLM-MaaS'!$B$11 | C11: ='LLM-MaaS'!$B$11 | D11: ='LLM-MaaS'!$B$11 | E11: US$ 0,21 por run premium, MEDIDO. Acotado por el kill-switch de la aplicación.
A13: TOTAL MENSUAL | B13: =Detalle!J30+'LLM-MaaS'!$B$11 | C13: =Detalle!K30+'LLM-MaaS'!$B$11 | D13: =Detalle!L30+'LLM-MaaS'!$B$11
A14: TOTAL MENSUAL (S/) | B14: =B13*Parametros!$B$8 | C14: =C13*Parametros!$B$8 | D14: =D13*Parametros!$B$8
A15: TOTAL ANUAL (US$) | B15: =B13*12 | C15: =C13*12 | D15: =D13*12
A16: TOTAL ANUAL con compromiso (US$) | B16: =B13*12*(1-Parametros!$B$10) | C16: =C13*12*(1-Parametros!$B$10) | D16: =D13*12*(1-Parametros!$B$10)
A18: Tres cosas que conviene decir al presentar este número
A19: 1. Los precios unitarios son ESTIMACIONES documentadas, no tarifas descargadas de la web de Huawei: la compañía solo las publica dentro de su calculador, que es JavaScript. La hoja 'Supuestos' dice cómo verificar cada una en minutos, y el libro se recalcula solo al cambiarlas.
A20: 2. El coste del LLM SÍ está medido en este proyecto (US$ 0,19-0,23 por consulta premium) y además está acotado por software: el kill-switch corta el gasto al llegar al tope sin devolver errores.
A21: 3. Hasta el CDR del 28 de agosto el escenario correcto es el A (encender solo para ensayos), que cuesta una fracción del 24×7. Pasar a B es una decisión de servicio, no de infraestructura.

Sheet Leeme
A1: Presupuesto de infraestructura — AgroScout IA en Huawei Cloud
A2: CITEagroindustrial Chavimochic · elaborado 2026-08-02 · región LA-Santiago
B5: ADVERTENCIA IMPORTANTE SOBRE LOS PRECIOS
B6: Huawei Cloud NO publica una lista de precios en HTML: sus tarifas viven únicamente dentro del calculador (https://www.huaweicloud.com/intl/en-us/pricing/calculator.html), que es una aplicación JavaScript y no se puede leer de forma automática ni citar como fuente estable.
B7: Por eso este libro NO afirma tener los precios oficiales. Lo que hace es mejor para un presupuesto que se va a presentar: cada precio unitario es una CELDA DE ENTRADA (fondo amarillo) con su estimación mín/esperado/máx documentada, y todo lo demás son fórmulas. En cuanto usted pegue los números del calculador, los totales, los escenarios y el resumen se recalculan solos.
B8: La hoja 'Supuestos' explica de dónde sale cada estimación y cómo verificarla en el calculador, paso a paso y con los filtros exactos.
B10: CÓDIGO DE COLORES
B11: Amarillo → celda de entrada: usted la edita con el dato del calculador o del contrato.
B12: Verde → dato MEDIDO en este proyecto, no estimado (p. ej. el coste por run del LLM).
B13: Naranja → total calculado. No editar: son fórmulas.
B15: CÓMO USAR ESTE LIBRO
B16: 1. Abra 'Parámetros' y ajuste horas/mes, tipo de cambio, impuestos y descuento por compromiso anual.
B17: 2. Vaya al calculador de Huawei con la región LA-Santiago y reemplace los precios unitarios de la hoja 'Detalle' (columnas G, H, I).
B18: 3. Revise 'LLM-MaaS': el coste por consulta ya está medido en el proyecto; solo defina el volumen mensual esperado.
... B26: Dominio y su renovación · horas de desarrollo e implantación · soporte de pago de Huawei (el plan Basic es gratuito) · licencias de terceros · impuestos locales si el contrato se firma con un socio peruano (parámetro editable en 'Parámetros').

Sheet Parametros
A1: Parámetros del presupuesto
A2: Cambie aquí y todo el libro se recalcula
A4: Parámetro | B4: Valor | C4: Unidad | D4: Nota
A5: Región | B5: LA-Santiago | C5: — | D5: La región de Huawei Cloud más cercana a Perú (~40-60 ms desde Lima). Requiere cuenta Huawei Cloud INTERNATIONAL, no la del sitio de China.
A6: Horas por mes (24×7) | B6: 730 | C6: h | D6: Convención de facturación en la nube: 365×24/12 = 730.
A7: Horas/mes escenario demo | B7: 80 | C7: h | D7: ECS y RDS encendidos solo para ensayos y la demo del CDR. El almacenamiento se paga igual.
A8: Tipo de cambio USD → PEN | B8: 3.75 | C8: S/ por US$ | D8: EDITAR con el tipo de cambio del día de la presentación.
A9: Impuestos aplicables | B9: 0 | C9: % | D9: 0 % si se factura directo con Huawei Cloud International. Si se contrata vía socio peruano, poner 18 % (IGV).
A10: Descuento por compromiso anual | B10: 0.35 | C10: % | D10: Prepago anual de ECS y RDS. VERIFICAR el descuento real en el calculador; 30-40 % es lo habitual.
A11: Runs premium por mes | B11: 100 | C11: runs | D11: Consultas completas (5 etapas LLM). Ver hoja LLM-MaaS.
A12: Tráfico saliente mensual | B12: 30 | C12: GB | D12: SPA (173 KB), PDFs (~200 KB c/u) y API. Estimación conservadora para uso de demo y piloto.

Sheet Detalle
A1: Detalle mensual de infraestructura — escenario MVP 24×7
A2: Columnas G, H, I = celdas de entrada (precio unitario). Todo lo demás son fórmulas.
A4: Categoría | B4: Concepto | C4: Especificación | D4: Unidad | E4: Cant. | F4: Uso/mes | G4: P. mín | H4: P. esperado | I4: P. máx | J4: Coste mín | K4: Coste esperado | L4: Coste máx | M4: Confianza | N4: Cómo verificarlo en el calculador
A5: Cómputo | B5: ECS s7n.xlarge.2 | C5: 4 vCPU · 8 GB RAM · Ubuntu 22.04 | D5: US$/hora | E5: 1 | F5: =Parametros!$B$6 | G5: 0.096 | H5: 0.125 | I5: 0.15 | J5: =$E5*$F5*G5 | K5: =$E5*$F5*H5 | L5: =$E5*$F5*I5 | M5: Media | N5: Calculator → ECS → LA-Santiago → General computing-plus s7n → 4 vCPU/8 GB → Pay-per-use.
A6: Cómputo | B6: Disco de sistema | C6: EVS SSD de propósito general, 40 GB | D6: US$/GB-mes | E6: 40 | F6: 1 | G6: 0.1 | H6: 0.12 | I6: 0.15 | J6: =$E6*$F6*G6 | K6: =$E6*$F6*H6 | L6: =$E6*$F6*I6 | M6: Media | N6: Calculator → EVS → General Purpose SSD → 40 GB. Se factura por GB-mes, no por uso.
A7: Cómputo | B7: Imagen del SO | C7: Ubuntu 22.04 LTS (imagen pública) | D7: US$/mes | E7: 1 | F7: 1 | G7: 0 | H7: 0 | I7: 0 | J7: =$E7*$F7*G7 | K7: =$E7*$F7*H7 | L7: =$E7*$F7*I7 | M7: Alta | N7: Las imágenes públicas no tienen coste de licencia.
A8: Base de datos | B8: RDS PostgreSQL 16 | C8: rds.pg.n1.large.2 · 2 vCPU/4 GB · nodo único | D8: US$/hora | E8: 1 | F8: =Parametros!$B$6 | G8: 0.07 | H8: 0.095 | I8: 0.12 | J8: =$E8*$F8*G8 | K8: =$E8*$F8*H8 | L8: =$E8*$F8*I8 | M8: Media | N8: Calculator → RDS → PostgreSQL → Single → 2 vCPU/4 GB. La opción Primary/Standby DUPLICA este importe.
A9: Base de datos | B9: Almacenamiento RDS | C9: SSD en la nube, 40 GB (mínimo) | D9: US$/GB-mes | E9: 40 | F9: 1 | G9: 0.15 | H9: 0.18 | I9: 0.22 | J9: =$E9*$F9*G9 | K9: =$E9*$F9*H9 | L9: =$E9*$F9*I9 | M9: Media | N9: Mismo asistente, apartado Storage. 40 GB es el mínimo que admite RDS.
A10: Base de datos | B10: Backup automático + PITR | C10: Retención 7 días | D10: US$/mes | E10: 1 | F10: 1 | G10: 0 | H10: 0 | I10: 3 | J10: =$E10*$F10*G10 | K10: =$E10*$F10*H10 | L10: =$E10*$F10*I10 | M10: Baja | N10: Huawei suele incluir sin cargo un backup del tamaño del almacenamiento contratado; el exceso se cobra. CONFIRMAR.
A11: Almacenamiento | B11: EVS de datos | C11: SSD 100 GB montado en /data (índice + snapshot) | D11: US$/GB-mes | E11: 100 | F11: 1 | G11: 0.1 | H11: 0.12 | I11: 0.15 | J11: =$E11*$F11*G11 | K11: =$E11*$F11*H11 | L11: =$E11*$F11*I11 | M11: Media | N11: Calculator → EVS → General Purpose SSD → 100 GB.
A12: Almacenamiento | B12: OBS Standard | C12: PDFs + snapshot + pesos bge-m3 (~20 GB) | D12: US$/GB-mes | E12: 20 | F12: 1 | G12: 0.019 | H12: 0.024 | I12: 0.03 | J12: =$E12*$F12*G12 | K12: =$E12*$F12*H12 | L12: =$E12*$F12*I12 | M12: Media | N12: Calculator → OBS → Standard storage → región LA-Santiago.
A13: Almacenamiento | B13: OBS peticiones y salida | C13: Volumen bajo: demo y sincronización del nodo | D13: US$/mes | E13: 1 | F13: 1 | G13: 0.5 | H13: 1 | I13: 2 | J13: =$E13*$F13*G13 | K13: =$E13*$F13*H13 | L13: =$E13*$F13*I13 | M13: Baja | N13: Se cobra por cada 10.000 peticiones y por tráfico saliente. Difícil de precisar sin uso real.
A14: Almacenamiento | B14: CBR — respaldo del disco | C14: Copia diaria de /data, retención 7 días | D14: US$/GB-mes | E14: 100 | F14: 1 | G14: 0.05 | H14: 0.06 | I14: 0.08 | J14: =$E14*$F14*G14 | K14: =$E14*$F14*H14 | L14: =$E14*$F14*I14 | M14: Media | N14: Calculator → CBR → Cloud Server Backup → 100 GB de capacidad de bóveda.
A15: Red | B15: EIP — cargo por IP | C15: 1 IP elástica asociada al ECS | D15: US$/hora | E15: 1 | F15: =Parametros!$B$6 | G15: 0.005 | H15: 0.007 | I15: 0.01 | J15: =$E15*$F15*G15 | K15: =$E15*$F15*H15 | L15: =$E15*$F15*I15 | M15: Media | N15: Calculator → EIP → Pay-per-use → facturación por tráfico. El cargo por IP es aparte.
A16: Red | B16: Tráfico saliente | C16: SPA, API y descarga de PDFs | D16: US$/GB | E16: 1 | F16: =Parametros!$B$12 | G16: 0.08 | H16: 0.09 | I16: 0.12 | J16: =$E16*$F16*G16 | K16: =$E16*$F16*H16 | L16: =$E16*$F16*I16 | M16: Media | N16: El tráfico ENTRANTE no se cobra. Solo se paga la salida a internet.
A17: Operación | B17: LTS — logs | C17: nginx + contenedor, ~2 GB/mes, retención 7 días | D17: US$/GB | E17: 1 | F17: 2 | G17: 0.3 | H17: 0.4 | I17: 0.5 | J17: =$E17*$F17*G17 | K17: =$E17*$F17*H17 | L17: =$E17*$F17*I17 | M17: Baja | N17: Suele haber una cuota gratuita mensual de ingesta; comprobarla antes de presupuestar.
A18: Operación | B18: CES + SMN — alarmas | C18: 5 alarmas con aviso por correo | D18: US$/mes | E18: 1 | F18: 1 | G18: 0 | H18: 0 | I18: 1 | J18: =$E18*$F18*G18 | K18: =$E18*$F18*H18 | L18: =$E18*$F18*I18 | M18: Media | N18: La monitorización básica de CES y el correo de SMN son gratuitos en volúmenes bajos.
A19: Operación | B19: DAS — consola SQL | C19: Acceso a RDS desde el navegador | D19: US$/mes | E19: 1 | F19: 1 | G19: 0 | H19: 0 | I19: 0 | J19: =$E19*$F19*G19 | K19: =$E19*$F19*H19 | L19: =$E19*$F19*I19 | M19: Media | N19: La edición estándar de DAS es gratuita.
A20: Operación | B20: SCM — certificado TLS | C20: Certificado de dominio único | D20: US$/mes | E20: 1 | F20: 1 | G20: 0 | H20: 0 | I20: 0 | J20: =$E20*$F20*G20 | K20: =$E20*$F20*H20 | L20: =$E20*$F20*I20 | M20: Media | N20: Existe certificado gratuito. Alternativa sin coste: Let's Encrypt en el propio nginx.
A21: Operación | B21: DNS — zona pública | C21: 1 zona alojada | D21: US$/mes | E21: 1 | F21: 1 | G21: 0.5 | H21: 0.5 | I21: 0.5 | J21: =$E21*$F21*G21 | K21: =$E21*$F21*H21 | L21: =$E21*$F21*I21 | M21: Media | N21: Coste bajo y estable. No incluye el registro del dominio.
B23: SUBTOTALES POR CATEGORÍA
B24: Cómputo | J24: =SUMIF($A$5:$A$21,$B24,J$5:J$21) | K24: =SUMIF($A$5:$A$21,$B24,K$5:K$21) | L24: =SUMIF($A$5:$A$21,$B24,L$5:L$21)
B25: Base de datos | J25: =SUMIF($A$5:$A$21,$B25,J$5:J$21) | K25: =SUMIF($A$5:$A$21,$B25,K$5:K$21) | L25: =SUMIF($A$5:$A$21,$B25,L$5:L$21)
B26: Almacenamiento | J26: =SUMIF($A$5:$A$21,$B26,J$5:J$21) | K26: =SUMIF($A$5:$A$21,$B26,K$5:K$21) | L26: =SUMIF($A$5:$A$21,$B26,L$5:L$21)
B27: Red | J27: =SUMIF($A$5:$A$21,$B27,J$5:J$21) | K27: =SUMIF($A$5:$A$21,$B27,K$5:K$21) | L27: =SUMIF($A$5:$A$21,$B27,L$5:L$21)
B28: Operación | J28: =SUMIF($A$5:$A$21,$B28,J$5:J$21) | K28: =SUMIF($A$5:$A$21,$B28,K$5:K$21) | L28: =SUMIF($A$5:$A$21,$B28,L$5:L$21)
B30: TOTAL INFRAESTRUCTURA (mes) | J30: =SUM(J24:J28) | K30: =SUM(K24:K28) | L30: =SUM(L24:L28)

Sheet LLM-MaaS
A1: Consumo de LLM — ModelArts MaaS
A2: Único bloque con datos MEDIDOS en el proyecto, no estimados
A4: Concepto | B4: Valor | C4: Unidad | D4: Origen del dato
A5: Coste por run premium (5 etapas, en frío) | B5: 0.21 | C5: US$/run | D5: MEDIDO el 2026-08-02 y anotado en .env.example: entre US$ 0,19 y 0,23. Tres de las cinco etapas usan glm-5.2.
A6: Coste por run gratuito (3 etapas) | B6: 0.05 | C6: US$/run | D6: Estimado a partir del anterior: sin las etapas 4 y 5, que son las caras.
A7: Runs premium al mes | B7: =Parametros!$B$11 | C7: runs | D7: Parámetro editable en la hoja 'Parámetros'.
A8: Runs gratuitos al mes | B8: 200 | C8: runs | D8: EDITAR. En el plan gratuito el paywall corta antes de la etapa 4.
A9: Ahorro por cache de respuestas | B9: 0.3 | C9: % | D9: El envoltorio etapa() cachea por (entrada, modelo, etapa, snapshot). En demos con consultas repetidas el ahorro real es mayor.
A11: COSTE MENSUAL DE LLM | B11: =(B5*B7+B6*B8)*(1-B9)
A13: Control de gasto ya implementado en la aplicación
A14: El kill-switch de la Semana 3 (PRESUPUESTO_GLOBAL_MES_USD, hoy 10) corta TODAS las llamadas al LLM al superar el tope: los runs siguen devolviendo 200 con informe parcial y motivo 'presupuesto'. Nunca un error.
A15: Con US$ 0,21 por run premium, un tope de US$ 10/mes son ~45 runs para toda la institución: sobra para la demo del CDR y se queda corto para uso real. Subirlo es una decisión consciente, no un descuido.
A16: Hay además topes por run (US$ 0,25) y por usuario/mes (US$ 2 gratuito, US$ 10 premium).

Sheet Produccion
A1: Escenario C · Producción CITE — detalle por línea
A2: Fase 2 del ADR-003: 100-300 organizaciones · 2 réplicas de API con balanceador · base en alta disponibilidad
A4: Categoría | B4: Concepto | C4: Especificación | D4: Unidad | E4: Cant. | F4: Uso/mes | G4: P. mín | H4: P. esperado | I4: P. máx | J4: Coste mín | K4: Coste esperado | L4: Coste máx | M4: Confianza | N4: Por qué entra en producción y no en el MVP
A5: Cómputo | B5: ECS s7n.xlarge.2 × 2 | C5: 2 réplicas de la API detrás del balanceador | D5: US$/hora | E5: 2 | F5: =Parametros!$B$6 | G5: 0.096 | H5: 0.125 | I5: 0.15 | J5: =$E5*$F5*G5 | K5: =$E5*$F5*H5 | L5: =$E5*$F5*I5 | M5: Media | N5: ADR-003 fase 2: se replica al superar p95 o CPU sostenida. Cada réplica carga su propia copia de bge-m3 (2,3 GB).
A6: Cómputo | B6: Discos de sistema | C6: EVS SSD 40 GB × 2 nodos | D6: US$/GB-mes | E6: 80 | F6: 1 | G6: 0.1 | H6: 0.12 | I6: 0.15 | J6: =$E6*$F6*G6 | K6: =$E6*$F6*H6 | L6: =$E6*$F6*I6 | M6: Media | N6: Uno por nodo.
A7: Cómputo | B7: ELB — balanceador | C7: Compartido, 1 listener HTTPS | D7: US$/hora | E7: 1 | F7: =Parametros!$B$6 | G7: 0.02 | H7: 0.03 | I7: 0.045 | J7: =$E7*$F7*G7 | K7: =$E7*$F7*H7 | L7: =$E7*$F7*I7 | M7: Baja | N7: Sin balanceador no hay dos nodos. Se factura por hora más unidades de capacidad según tráfico.
A8: Base de datos | B8: RDS PostgreSQL en HA | C8: 4 vCPU/8 GB · primario + en espera | D8: US$/hora | E8: 1 | F8: =Parametros!$B$6 | G8: 0.3 | H8: 0.38 | I8: 0.46 | J8: =$E8*$F8*G8 | K8: =$E8*$F8*H8 | L8: =$E8*$F8*I8 | M8: Baja | N8: DUPLICA el precio del nodo único y sube de flavor. Es la línea más cara del escenario y la primera a discutir.
A9: Base de datos | B9: Almacenamiento RDS | C9: SSD 100 GB | D9: US$/GB-mes | E9: 100 | F9: 1 | G9: 0.15 | H9: 0.18 | I9: 0.22 | J9: =$E9*$F9*G9 | K9: =$E9*$F9*H9 | L9: =$E9*$F9*I9 | M9: Media | N9: Crece con el histórico de ejecuciones y el cache de respuestas.
A10: Base de datos | B10: Réplica de lectura (opcional) | C10: 4 vCPU/8 GB · solo lecturas del panel | D10: US$/hora | E10: 0 | F10: =Parametros!$B$6 | G10: 0.15 | H10: 0.19 | I10: 0.23 | J10: =$E10*$F10*G10 | K10: =$E10*$F10*H10 | L10: =$E10*$F10*I10 | M10: Baja | N10: Cantidad en 0: el ADR no la pide en fase 2. Poner 1 si el panel del CITE penaliza la escritura.
A11: Almacenamiento | B11: OBS Standard | C11: Fuente de verdad: snapshots, informes, corpus (~100 GB) | D11: US$/GB-mes | E11: 100 | F11: 1 | G11: 0.019 | H11: 0.024 | I11: 0.03 | J11: =$E11*$F11*G11 | K11: =$E11*$F11*H11 | L11: =$E11*$F11*I11 | M11: Media | N11: En fase 2 el OBS pasa a ser la fuente de verdad y el disco local es cache.
A12: Almacenamiento | B12: OBS peticiones y salida | C12: Pull de snapshots por nodo + descargas de informes | D12: US$/mes | E12: 1 | F12: 1 | G12: 3 | H12: 5 | I12: 10 | J12: =$E12*$F12*G12 | K12: =$E12*$F12*H12 | L12: =$E12*$F12*I12 | M12: Baja | N12: Cada nodo descarga el snapshot al arrancar.
A13: Almacenamiento | B13: CBR — respaldo | C13: Bóveda de 200 GB | D13: US$/GB-mes | E13: 200 | F13: 1 | G13: 0.05 | H13: 0.06 | I13: 0.08 | J13: =$E13*$F13*G13 | K13: =$E13*$F13*H13 | L13: =$E13*$F13*I13 | M13: Media | N13: Dos nodos y más datos.
A14: Red | B14: EIP del balanceador | C14: 1 IP elástica | D14: US$/hora | E14: 1 | F14: =Parametros!$B$6 | G14: 0.005 | H14: 0.007 | I14: 0.01 | J14: =$E14*$F14*G14 | K14: =$E14*$F14*H14 | L14: =$E14*$F14*I14 | M14: Media | N14: Los nodos dejan de tener IP pública propia.
A15: Red | B15: Tráfico saliente | C15: 200 GB/mes con usuarios reales | D15: US$/GB | E15: 1 | F15: 200 | G15: 0.08 | H15: 0.09 | I15: 0.12 | J15: =$E15*$F15*G15 | K15: =$E15*$F15*H15 | L15: =$E15*$F15*I15 | M15: Baja | N15: Estimación: ~7× el tráfico de piloto. Medir un mes real antes de firmar.
A16: Red | B16: NAT Gateway | C16: Salida con IP fija para el agente web | D16: US$/hora | E16: 1 | F16: =Parametros!$B$6 | G16: 0.035 | H16: 0.05 | I16: 0.07 | J16: =$E16*$F16*G16 | K16: =$E16*$F16*H16 | L16: =$E16*$F16*I16 | M16: Baja | N16: Lo exige el agente de la fase F4: identificarse ante los sitios y respetar rate-limits pide IP fija.
A17: Red | B17: CDN | C17: SPA y estáticos, ~100 GB/mes | D17: US$/GB | E17: 1 | F17: 100 | G17: 0.06 | H17: 0.08 | I17: 0.11 | J17: =$E17*$F17*G17 | K17: =$E17*$F17*H17 | L17: =$E17*$F17*I17 | M17: Baja | N17: Con usuarios repartidos deja de tener sentido servir la SPA desde el ECS.
A18: Red | B18: WAF | C18: Modo nube, edición estándar | D18: US$/mes | E18: 1 | F18: 1 | G18: 30 | H18: 45 | I18: 70 | J18: =$E18*$F18*G18 | K18: =$E18*$F18*H18 | L18: =$E18*$F18*I18 | M18: Baja | N18: Un servicio institucional expuesto a internet con datos de terceros. Recortable si el CITE acepta el riesgo.
A19: Operación | B19: LTS — logs | C19: ~10 GB/mes de 2 nodos | D19: US$/GB | E19: 1 | F19: 10 | G19: 0.3 | H19: 0.4 | I19: 0.5 | J19: =$E19*$F19*G19 | K19: =$E19*$F19*H19 | L19: =$E19*$F19*I19 | M19: Baja | N19: Más nodos y más tráfico.
A20: Operación | B20: CES + SMN | C20: Alarmas y notificación | D20: US$/mes | E20: 1 | F20: 1 | G20: 1 | H20: 2 | I20: 4 | J20: =$E20*$F20*G20 | K20: =$E20*$F20*H20 | L20: =$E20*$F20*I20 | M20: Media | N20: Más métricas y más destinatarios.
A21: Operación | B21: DNS | C21: 1 zona pública | D21: US$/mes | E21: 1 | F21: 1 | G21: 0.5 | H21: 0.5 | I21: 0.5 | J21: =$E21*$F21*G21 | K21: =$E21*$F21*H21 | L21: =$E21*$F21*I21 | M21: Media | N21: Igual que en el MVP.
A22: Operación | B22: Soporte de pago (opcional) | C22: Plan Business | D22: US$/mes | E22: 0 | F22: 1 | G22: 100 | H22: 150 | I22: 200 | J22: =$E22*$F22*G22 | K22: =$E22*$F22*H22 | L22: =$E22*$F22*I22 | M22: Baja | N22: Cantidad en 0: el plan Basic es gratuito. Un servicio institucional con SLA suele necesitar más.
B24: SUBTOTALES POR CATEGORÍA
B25: Cómputo | J25: =SUMIF($A$5:$A$22,$B25,J$5:J$22) | K25: =SUMIF($A$5:$A$22,$B25,K$5:K$22) | L25: =SUMIF($A$5:$A$22,$B25,L$5:L$22)
B26: Base de datos | J26: =SUMIF($A$5:$A$22,$B26,J$5:J$22) | K26: =SUMIF($A$5:$A$22,$B26,K$5:K$22) | L26: =SUMIF($A$5:$A$22,$B26,L$5:L$22)
B27: Almacenamiento | J27: =SUMIF($A$5:$A$22,$B27,J$5:J$22) | K27: =SUMIF($A$5:$A$22,$B27,K$5:K$22) | L27: =SUMIF($A$5:$A$22,$B27,L$5:L$22)
B28: Red | J28: =SUMIF($A$5:$A$22,$B28,J$5:J$22) | K28: =SUMIF($A$5:$A$22,$B28,K$5:K$22) | L28: =SUMIF($A$5:$A$22,$B28,L$5:L$22)
B29: Operación | J29: =SUMIF($A$5:$A$22,$B29,J$5:J$22) | K29: =SUMIF($A$5:$A$22,$B29,K$5:K$22) | L29: =SUMIF($A$5:$A$22,$B29,L$5:L$22)
B31: TOTAL INFRAESTRUCTURA PRODUCCIÓN (mes) | J31: =SUM(J25:J29) | K31: =SUM(K25:K29) | L31: =SUM(L25:L29)
B33: PALANCAS DE RECORTE — qué se ahorra y qué se pierde
B34: Palanca | C34: Ahorro mensual | N34: Qué se pierde
B35: RDS sin alta disponibilidad | C35: =-Produccion!$K$8/2 | N35: Vuelve al nodo único: una caída de la base es una restauración manual, no una conmutación.
B36: Sin WAF | C36: =-Produccion!$K$18 | N36: El servicio queda expuesto sin filtro de aplicación. Decisión del CITE, no técnica.
B37: Sin NAT Gateway | C37: =-Produccion!$K$16 | N37: El agente web sale sin IP fija: peor ciudadanía ante los sitios y riesgo de bloqueo.
B38: Un solo nodo de API (sin ELB) | C38: =-Produccion!$K$5/2-Produccion!$K$7 | N38: Se acaba la alta disponibilidad del cómputo y las ventanas de despliegue sin corte.
B39: Sin CDN | C39: =-Produccion!$K$17 | N39: La SPA se sirve desde el ECS. Aceptable si los usuarios están todos en Perú.

Sheet Usuarios
A1: Proyección de usuarios por escenario
A2: Cuánta gente sostiene cada escenario, y qué se agota primero: la máquina o el presupuesto
A4: Supuesto del modelo | B4: Valor | C4: Unidad | D4: De dónde sale
A5: Consultas por usuario activo al mes | B5: 10 | C5: consultas | D5: EDITAR. Un analista del CITE evaluando insumos no consulta a diario: 10/mes es un uso real y sostenido.
A6: Usuarios activos sobre registrados | B6: 0.5 | C6: % | D6: EDITAR. La mitad de las cuentas creadas usa el sistema en un mes dado. En piloto institucional suele ser menos.
A7: Usuarios por organización | B7: 3 | C7: usuarios | D7: EDITAR. Para traducir usuarios a organizaciones, que es la unidad del ADR-003 y del contrato.
A8: Duración media de un run (extremo a extremo) | B8: 25 | C8: segundos | D8: Dominada por el LLM: 5 etapas con generación de 3-10 s cada una. La búsqueda vectorial aporta 176 ms.
A9: CPU bloqueante por run | B9: 3.5 | C9: segundos | D9: Lo único que NO es asíncrono: embedding + búsqueda LanceDB (~0,5 s) y generación del PDF con WeasyPrint (~3 s). ESTIMADO: conviene medirlo con una prueba de carga antes de comprometer capacidad.
A10: Utilización objetivo del nodo | B10: 0.3 | C10: % | D10: No se planifica al 100 %: por encima del 30 % de ocupación del bucle de eventos la latencia p95 se dispara.
A11: Días laborables al mes | B11: 22 | C11: días | D11: El CITE consulta en horario de oficina.
A12: Carga concentrada en la hora punta | B12: 0.25 | C12: % | D12: Un cuarto de la jornada se concentra en una hora. Regla de planificación habitual.
A13: Tope global de LLM configurado | B13: 10 | C13: US$/mes | D13: PRESUPUESTO_GLOBAL_MES_USD del .env. Es el kill-switch: al superarse nadie ejecuta LLM.
A15: Métrica | B15: A · Demo y ensayos | C15: B · MVP 24×7 | D15: C · Producción CITE | E15: Cómo se calcula
A16: Runs premium al mes | B16: 20 | C16: =Parametros!$B$11 | D16: 500 | E16: A: ensayos del equipo. B: parámetro. C: fase 2 del ADR-003.
A17: Runs gratuitos al mes | B17: 0 | C17: ='LLM-MaaS'!$B$8 | D17: 2000 | E17: El plan gratuito corta en la etapa 3; cuesta ~4× menos por run.
A18: Runs totales al mes | B18: =B16+B17 | C18: =C16+C17 | D18: =D16+D17
A19: USUARIOS ACTIVOS que sostiene | B19: =B18/$B$5 | C19: =C18/$B$5 | D19: =D18/$B$5 | E19: Runs totales ÷ consultas por usuario activo.
A20: Usuarios registrados equivalentes | B20: =B19/$B$6 | C20: =C19/$B$6 | D20: =D19/$B$6 | E20: Activos ÷ tasa de actividad.
A21: Organizaciones equivalentes | B21: =B20/$B$7 | C21: =C20/$B$7 | D21: =D20/$B$7 | E21: La unidad del ADR-003 y del contrato multi-cooperativa.
A22: Consultas por día laborable | B22: =B18/$B$11 | C22: =C18/$B$11 | D22: =D18/$B$11
A23: Consultas en la hora punta | B23: =B21*$B$12 | C23: =C21*$B$12 | D23: =D21*$B$12
A24: Runs simultáneos en el pico | B24: =B22*$B$8/3600 | C24: =C22*$B$8/3600 | D24: =D22*$B$8/3600 | E24: Ley de Little: llegadas × duración. Menos de 1 significa que casi nunca coinciden dos consultas.
A25: Coste total mensual | B25: =Escenarios!$B$9 | C25: =Escenarios!$C$9 | D25: =Escenarios!$D$9 | E25: De la hoja 'Escenarios'.
A26: COSTE POR USUARIO ACTIVO / mes | B26: =B24/B19 | C26: =C24/C19 | D26: =D24/D19 | E26: El número que hay que comparar con el precio de la suscripción premium.
A27: Coste por consulta | B27: =B24/B18 | C27: =C24/C18 | D27: =D24/D18 | E27: Incluye infraestructura, no solo el LLM.
A29: ¿QUÉ SE AGOTA PRIMERO?
A30: Techo | B30: Usuarios activos | E30: Qué lo produce
A31: Techo por PRESUPUESTO de LLM (kill-switch actual) | B31: =($B$13/'LLM-MaaS'!$B$5)/$B$5 | E31: Con el tope global en US$ 10/mes y US$ 0,21 por run premium, la aplicación deja de llamar al LLM al llegar a ~48 consultas premium. Es una decisión de configuración, no un límite físico.
A32: Techo de CÓMPUTO de un nodo | B32: =(3600/$B$9*$B$10*8*$B$11)/$B$5 | E32: Con 3,5 s de CPU bloqueante por run al 30 % de ocupación, 8 h/día, 22 días. La RAM no entra: bge-m3 ocupa 2,3 GB fijos, no crece con los usuarios.
A33: Techo del POOL de conexiones a la base | B33: =5*3600/$B$8/$B$5*8*$B$11 | E33: adaptadores/db.py abre el pool con max_size=5. Cinco operaciones simultáneas de base, no cinco usuarios: cada run las usa unos milisegundos.
A34: CUELLO DE BOTELLA REAL (el menor de los tres) | B34: =MIN(B31:B33)
A36: Lectura de la proyección
A37: 1. La máquina no es el límite: nunca. Un solo nodo de 4 vCPU sostiene del orden de MILES de usuarios activos, porque un run pasa 25 s esperando al LLM y solo ~3,5 s ocupando CPU. Los dos nodos y el balanceador del escenario C se pagan por DISPONIBILIDAD, no por capacidad: si uno se cae, el servicio sigue.
A38: 2. El límite real es el dinero del LLM, y hoy está puesto muy bajo. Con el kill-switch en US$ 10/mes, el sistema atiende ~5 usuarios activos antes de degradar a 'sin dato'. Para el CDR es correcto; para un piloto con el CITE hay que subirlo a conciencia y decir cuánto cuesta cada tramo.
A39: 3. El coste por usuario baja rápido con la escala: el grueso de la factura es fijo (ECS, RDS, EIP) y solo el LLM crece con el uso. Es el argumento económico del paywall: la cuota por plan es lo que impide que un usuario intensivo se coma el margen.
A40: 4. Lo que hay que medir antes de firmar capacidad: los 3,5 s de CPU bloqueante por run son una ESTIMACIÓN. La generación del PDF es síncrona y bloquea el bucle de eventos; si resulta ser el doble, el techo de cómputo se parte por dos (y seguiría estando muy por encima de la demanda).

Sheet Crecimiento
A1: Crecimiento de datos a 12 meses
A2: Huella por consulta MEDIDA sobre las tablas de auditoría del proyecto, no estimada
A4: Huella por consulta | B4: KB | C4: Origen del dato
A5: Etapa 1 · InterpretarInsumo | B5: 0.4 | C5: MEDIDO: 50 filas reales en etapas_ejecucion. entrada+salida en JSON.
A6: Etapa 2 · MatchProductos | B6: 15.7 | C6: MEDIDO: 26 filas. Guarda los 30 productos con sus ingredientes.
A7: Etapa 2b · MapaComercial | B7: 59.3 | C7: MEDIDO: 10 filas. Es la etapa más pesada, 5× cualquier otra: su salida_json lleva el mapa comercial completo. Máximo observado 74 KB.
A8: Etapa 3 · InsightMercado | B8: 11.8 | C8: MEDIDO: 50 filas.
A9: Etapa 4 · Formulación (premium) | B9: 15 | C9: ESTIMADO: aún no hay filas históricas de la etapa separada en S3.
A10: Etapa 5 · Regulación (premium) | B10: 20 | C10: ESTIMADO: incluye el contexto del corpus regulatorio.
A11: Fila de ejecución + fila de informe | B11: 0.8 | C11: MEDIDO: metadatos, sin JSON.
A12: Cache LLM por llamada nueva | B12: 2.2 | C12: MEDIDO: 60 filas de cache_llm, 129,7 KB en total.
A13: PDF del informe | B13: 26 | C13: MEDIDO: 216 PDFs reales en informes/, 5,5 MB en total.
A15: TOTAL por consulta PREMIUM (6 etapas) | B15: =B5+B6+B7+B8+B9+B10+B11+B12*4*(1-'LLM-MaaS'!$B$9) | C15: 4 etapas con LLM; el cache evita guardar el 30 % de las llamadas.
A16: TOTAL por consulta GRATUITA (4 etapas) | B16: =B5+B6+B7+B8+B11+B12*2*(1-'LLM-MaaS'!$B$9) | C16: El paywall corta antes de las etapas 4 y 5.
A18: Crecimiento por snapshot de datos | B18: Valor | C18: Nota
A19: Productos por snapshot | B19: 29054 | C19: MEDIDO: los 5 insumos piloto del snapshot 2026-07.
A20: KB por producto (JSON + vector) | B20: 7.1 | C20: MEDIDO: 66 MB de JSON + 135 MB de índice LanceDB ÷ 29.054 productos.
A21: Tamaño de un snapshot (MB) | B21: =B19*B20/1024 | C21: Calculado. El snapshot actual pesa ~201 MB.
A22: Snapshots publicados al año | B22: 4 | C22: EDITAR. Trimestral es lo razonable; mensual multiplica por 3.
A23: ¿Se conservan los anteriores? | B23: Sí | C23: El versionado de OBS los guarda: es el respaldo de los datasets (H8 del ADR).
A26: ACUMULADO MES A MES
A27: Mes | B27: B · RDS (GB) | C27: B · OBS (GB) | D27: C · RDS (GB) | E27: C · OBS (GB) | F27: C · % del RDS presupuestado | G27: C · % del OBS presupuestado
A28: 1 | B28: =A28*(Usuarios!$C$16*$B$15+Usuarios!$C$17*$B$16)/1048576 | C28: =2.3+A28*(Usuarios!$C$18*$B$13)/1048576+(1+INT(A28*$B$22/12))*$B$21/1024 | D28: =A28*(Usuarios!$D$16*$B$15+Usuarios!$D$17*$B$16)/1048576 | E28: =2.3+A28*(Usuarios!$D$18*$B$13)/1048576+(1+INT(A28*$B$22/12))*$B$21/1024 | F28: =D28/Detalle!$E$9 | G28: =E28/Detalle!$E$11
A29: 2 | B29: =A29*(Usuarios!$C$16*$B$15+Usuarios!$C$17*$B$16)/1048576 | C29: =2.3+A29*(Usuarios!$C$18*$B$13)/1048576+(1+INT(A29*$B$22/12))*$B$21/1024 | D29: =A29*(Usuarios!$D$16*$B$15+Usuarios!$D$17*$B$16)/1048576 | E29: =2.3+A29*(Usuarios!$D$18*$B$13)/1048576+(1+INT(A29*$B$22/12))*$B$21/1024 | F29: =D29/Detalle!$E$9 | G29: =E29/Detalle!$E$11
A30: 3 | B30: =A30*(Usuarios!$C$16*$B$15+Usuarios!$C$17*$B$16)/1048576 | C30: =2.3+A30*(Usuarios!$C$18*$B$13)/1048576+(1+INT(A30*$B$22/12))*$B$21/1024 | D30: =A30*(Usuarios!$D$16*$B$15+Usuarios!$D$17*$B$16)/1048576 | E30: =2.3+A30*(Usuarios!$D$18*$B$13)/1048576+(1+INT(A30*$B$22/12))*$B$21/1024 | F30: =D30/Detalle!$E$9 | G30: =E30/Detalle!$E$11
A31: 4 | B31: =A31*(Usuarios!$C$16*$B$15+Usuarios!$C$17*$B$16)/1048576 | C31: =2.3+A31*(Usuarios!$C$18*$B$13)/1048576+(1+INT(A31*$B$22/12))*$B$21/1024 | D31: =A31*(Usuarios!$D$16*$B$15+Usuarios!$D$17*$B$16)/1048576 | E31: =2.3+A31*(Usuarios!$D$18*$B$13)/1048576+(1+INT(A31*$B$22/12))*$B$21/1024 | F31: =D31/Detalle!$E$9 | G31: =E31/Detalle!$E$11
A32: 5 | B32: =A32*(Usuarios!$C$16*$B$15+Usuarios!$C$17*$B$16)/1048576 | C32: =2.3+A32*(Usuarios!$C$18*$B$13)/1048576+(1+INT(A32*$B$22/12))*$B$21/1024 | D32: =A32*(Usuarios!$D$16*$B$15+Usuarios!$D$17*$B$16)/1048576 | E32: =2.3+A32*(Usuarios!$D$18*$B$13)/1048576+(1+INT(A32*$B$22/12))*$B$21/1024 | F32: =D32/Detalle!$E$9 | G32: =E32/Detalle!$E$11
A33: 6 | B33: =A33*(Usuarios!$C$16*$B$15+Usuarios!$C$17*$B$16)/1048576 | C33: =2.3+A33*(Usuarios!$C$18*$B$13)/1048576+(1+INT(A33*$B$22/12))*$B$21/1024 | D33: =A33*(Usuarios!$D$16*$B$15+Usuarios!$D$17*$B$16)/1048576 | E33: =2.3+A33*(Usuarios!$D$18*$B$13)/1048576+(1+INT(A33*$B$22/12))*$B$21/1024 | F33: =D33/Detalle!$E$9 | G33: =E33/Detalle!$E$11
A34: 7 | B34: =A34*(Usuarios!$C$16*$B$15+Usuarios!$C$17*$B$16)/1048576 | C34: =2.3+A34*(Usuarios!$C$18*$B$13)/1048576+(1+INT(A34*$B$22/12))*$B$21/1024 | D34: =A34*(Usuarios!$D$16*$B$15+Usuarios!$D$17*$B$16)/1048576 | E34: =2.3+A34*(Usuarios!$D$18*$B$13)/1048576+(1+INT(A34*$B$22/12))*$B$21/1024 | F34: =D34/Detalle!$E$9 | G34: =E34/Detalle!$E$11
A35: 8 | B35: =A35*(Usuarios!$C$16*$B$15+Usuarios!$C$17*$B$16)/1048576 | C35: =2.3+A35*(Usuarios!$C$18*$B$13)/1048576+(1+INT(A35*$B$22/12))*$B$21/1024 | D35: =A35*(Usuarios!$D$16*$B$15+Usuarios!$D$17*$B$16)/1048576 | E35: =2.3+A35*(Usuarios!$D$18*$B$13)/1048576+(1+INT(A35*$B$22/12))*$B$21/1024 | F35: =D35/Detalle!$E$9 | G35: =E35/Detalle!$E$11
A36: 9 | B36: =A36*(Usuarios!$C$16*$B$15+Usuarios!$C$17*$B$16)/1048576 | C36: =2.3+A36*(Usuarios!$C$18*$B$13)/1048576+(1+INT(A36*$B$22/12))*$B$21/1024 | D36: =A36*(Usuarios!$D$16*$B$15+Usuarios!$D$17*$B$16)/1048576 | E36: =2.3+A36*(Usuarios!$D$18*$B$13)/1048576+(1+INT(A36*$B$22/12))*$B$21/1024 | F36: =D36/Detalle!$E$9 | G36: =E36/Detalle!$E$11
A37: 10 | B37: =A37*(Usuarios!$C$16*$B$15+Usuarios!$C$17*$B$16)/1048576 | C37: =2.3+A37*(Usuarios!$C$18*$B$13)/1048576+(1+INT(A37*$B$22/12))*$B$21/1024 | D37: =A37*(Usuarios!$D$16*$B$15+Usuarios!$D$17*$B$16)/1048576 | E37: =2.3+A37*(Usuarios!$D$18*$B$13)/1048576+(1+INT(A37*$B$22/12))*$B$21/1024 | F37: =D37/Detalle!$E$9 | G37: =E37/Detalle!$E$11
A38: 11 | B38: =A38*(Usuarios!$C$16*$B$15+Usuarios!$C$17*$B$16)/1048576 | C38: =2.3+A38*(Usuarios!$C$18*$B$13)/1048576+(1+INT(A38*$B$22/12))*$B$21/1024 | D38: =A38*(Usuarios!$D$16*$B$15+Usuarios!$D$17*$B$16)/1048576 | E38: =2.3+A38*(Usuarios!$D$18*$B$13)/1048576+(1+INT(A38*$B$22/12))*$B$21/1024 | F38: =D38/Detalle!$E$9 | G38: =E38/Detalle!$E$11
A39: 12 | B39: =A39*(Usuarios!$C$16*$B$15+Usuarios!$C$17*$B$16)/1048576 | C39: =2.3+A39*(Usuarios!$C$18*$B$13)/1048576+(1+INT(A39*$B$22/12))*$B$21/1024 | D39: =A39*(Usuarios!$D$16*$B$15+Usuarios!$D$17*$B$16)/1048576 | E39: =2.3+A39*(Usuarios!$D$18*$B$13)/1048576+(1+INT(A39*$B$22/12))*$B$21/1024 | F39: =D39/Detalle!$E$9 | G39: =E39/Detalle!$E$11
A41: Veredicto
A42: 1. NADA se desborda en el primer año. Con el escenario C —250 usuarios activos, 2.500 consultas al mes— el RDS llega al mes 12 con unos 3 GB de los 40 GB contratados (7 %) y el OBS con unos 4 GB de los 20 GB (20 %). El almacenamiento presupuestado da para más de una década al ritmo del escenario C.
A43: 2. Lo que hace crecer la plataforma NO son los usuarios: son los snapshots. Un snapshot de los 5 insumos piloto pesa ~201 MB, y con versionado de OBS los anteriores se conservan. Pasar de 5 a 20 insumos multiplica por 4 el tamaño de CADA snapshot (~800 MB), y publicar mensualmente en vez de trimestralmente lo multiplica por 3 otra vez. Ahí sí hay que rehacer la cuenta: son los dos únicos parámetros que mueven la aguja.
A44: 3. Hallazgo: la etapa 2b ocupa 59 KB por consulta, cinco veces más que cualquier otra etapa, porque guarda el mapa comercial completo en salida_json. Hoy es irrelevante en volumen, pero es la línea que crecería si el mapa pasara de 30 a 200 productos. Si algún día molesta, la solución es guardar los identificadores y reconstruir el mapa desde el catálogo, no comprimir.
A45: 4. Hallazgo: cache_llm no tiene TTL ni purga. La clave incluye snapshot_version, así que las entradas viejas quedan lógicamente invalidadas pero las filas se acumulan. A 2,2 KB por fila no es un problema de espacio en años; conviene saberlo antes de que alguien lo descubra buscando otra cosa.
A46: 5. Lo que sí conviene automatizar desde el día 1: purgar los PDFs locales de /data/informes tras subirlos a OBS. Son 26 KB cada uno, pero el disco es el único almacén sin política de retención.

Sheet Ingesta
A1: Ingesta de datos — lo que el software traga en cada ciclo
A2: Tiempos y volúmenes MEDIDOS en los logs del ETL de la Semana 2 (datasets/2026-07/)
A4: Fuente | B4: Método | C4: Descargado | D4: Filas leídas | E4: Registros retenidos | F4: Tiempo medido | G4: Frecuencia | H4: Nota
A5: Open Food Facts | B5: Export masivo CSV.gz | C5: 2,0 GB | D5: 4.532.767 | E5: 28.236 | F5: 10 min 29 s | G5: Trimestral | H5: MEDIDO en etl_off_bulk.log: descarga 2 min 30 s (13 MB/s) + filtrado 7 min 59 s. Es el 97 % de toda la ingesta.
A6: USDA Branded | B6: API por insumo | C6: ~15 MB | D6: — | E6: 990 → 818 tras dedup | F6: 5-15 min | G6: Trimestral | H6: Requiere USDA_API_KEY. Filtra dataType=Branded y trae modifiedDate como fecha real.
A7: eCFR Title 21 | B7: API pública | C7: ~5 MB | D7: — | E7: 702 documentos | F7: ~10 min | G7: Semestral | H7: 99.333 palabras. NO cubre los insumos piloto: es normativa de aditivos.
A8: DIGESA | B8: Descarga de PDF + extracción | C8: ~20 MB | D8: — | E8: 32 documentos | F8: ~30 min | G8: Semestral | H8: 6.602 palabras. 5 PDFs quedaron fuera por ser escaneos. El sitio devuelve 403 si se piden páginas seguidas.
A9: Open Prices | B9: API por código de barras | C9: <1 MB | D9: — | E9: Por medir (sonda de S4) | F9: ~5 min | G9: Trimestral | H9: Aún no integrada. La sonda del TIER 1 de S4 mide primero la cobertura real.
A10: Agente web (fase F4) | B10: Tavily + extracción | C10: Variable | D10: — | E10: A cuarentena con TTL | F10: Por run | G10: Continua | H10: No entra en el MVP. Ingesta continua y de bajo volumen, con grounding check antes de promover.
A12: LO QUE ESTO SIGNIFICA
A13: Métrica del ciclo | B13: Valor | C13: Cómo sale
A14: Ratio de retención (filas) | B14: 0.0062 | C14: 28.236 de 4.532.767 filas de OFF. Se descarta el 99,4 %.
A15: Ratio de retención (bytes) | B15: 0.033 | C15: 66 MB de JSON retenidos de 2,0 GB descargados.
A16: Descarga por ciclo (GB) | B16: 2.05 | C16: OFF domina; el resto de fuentes son ruido a su lado.
A17: Tiempo de ingesta por ciclo (min) | B17: 70 | C17: OFF 10,5 + USDA 15 + eCFR 10 + DIGESA 30, con margen. Sin embeddings.
A18: Disco temporal necesario (GB) | B18: 5 | C18: El .gz de 2 GB más margen. Se lee en streaming: no se descomprime a disco.
A19: Coste del tráfico de ENTRADA | B19: 0 | C19: El ingress no se cobra en Huawei Cloud. Descargar 2 GB por ciclo es gratis.
A20: Snapshot resultante (MB) | B20: 201 | C20: 66 MB de JSON + 135 MB de índice vectorial.
A22: EL CUELLO DE LA INGESTA NO ES LA DESCARGA: SON LOS EMBEDDINGS
A23: Modo de indexación | B23: Velocidad medida | C23: 29.054 productos | D23: 116.000 productos (20 insumos) | E23: Nota
A24: GPU (RTX 4060, batch 128) | B24: 100-200 prod/s | C24: 15-30 min | D24: 1-2 horas | E24: MEDIDO en TIER 4 de la Semana 2. Es la máquina de desarrollo, no la nube.
A25: CPU (el ECS de producción) | B25: 4-5 prod/s | C25: 2-3 horas | D25: 7-8 horas | E25: El ECS NO tiene GPU. Reindexar entero en producción bloquea el nodo y compite con la API.
A26: Incremental (solo lo nuevo) | B26: 80 prod/s en GPU | C26: 10,2 s para 818 nuevos | D26: Proporcional al delta | E26: MEDIDO en TIER 7: etl/indexar_incremental.py compara por id y embebe solo lo que falta. Es el modo normal.
A28: ¿DÓNDE CORRE LA INGESTA? (hoy: en un portátil)
A29: Opción | B29: Coste anual | C29: Ventaja | D29: Inconveniente | E29: Veredicto
A30: A · Portátil con RTX 4060 y subida a OBS | B30: 0 | C30: Coste cero y es lo que ya funciona: TIER 4 y TIER 7 se hicieron así. | D30: La reproducibilidad depende de una máquina personal. Si esa máquina no está, no hay snapshot nuevo. | E30: Vale para el MVP
A31: B · En el ECS de producción, con CPU | B31: 0 | C31: Todo en la nube, sin piezas fuera del despliegue. | D31: 2-3 h de CPU al 100 % por ciclo completo compitiendo con la API: la latencia p95 se va al techo. | E31: Solo en modo incremental
A32: C · ECS con GPU encendido por horas | B32: 8 | C32: 1 hora por trimestre a ~US$ 1-2/h. Reproducible, en la nube y no toca el nodo de producción. | D32: Una pieza más que aprovisionar, aunque sea efímera. | E32: RECOMENDADA
A33: D · Nodo dedicado con GPU 24×7 | B33: 1500 | C33: Disponible siempre. | D33: Se paga el 100 % del mes para usarlo 4 horas al año. | E33: Descartada
A35: PROYECCIÓN ANUAL DE INGESTA
A36: Concepto | B36: 5 insumos (hoy) | C36: 20 insumos | D36: Nota
A37: Ciclos al año | B37: 4 | C37: 4 | D37: EDITAR. Trimestral. Mensual multiplica todo por 3.
A38: GB descargados al año | B38: =B37*2.05 | C38: =C37*2.05*1.0 | D38: El export de OFF es el mismo tamaño: no depende de cuántos insumos se filtren.
A39: Millones de filas procesadas | B39: =B37*4.53 | C39: =C37*4.53 | D39: Se lee el export entero en las dos hipótesis.
A40: Productos retenidos por ciclo | B40: 29054 | C40: 116000 | D40: El filtro es lo único que cambia al añadir insumos.
A41: MB de snapshot por ciclo | B41: =B40*7.1/1024 | C41: =C40*7.1/1024 | D41: 7,1 KB por producto entre JSON y vector (medido).
A42: GB acumulados al año en OBS | B42: =B37*B41/1024 | C42: =C37*C41/1024 | D42: Con versionado: los snapshots antiguos se conservan.
A43: Horas de indexación al año (GPU) | B43: =B37*B40/150/3600 | C43: =C37*C40/150/3600 | D43: A 150 prod/s. Reindexado COMPLETO; en incremental es una fracción.
A44: Horas de indexación al año (CPU) | B44: =B37*B40/4.5/3600 | C44: =C37*C40/4.5/3600 | D44: A 4,5 prod/s. Es lo que costaría hacerlo en el ECS de producción.
A45: Coste de la ingesta al año | B45: =$B$32 | C45: =$B$32*2 | D45: Opción C: ECS con GPU por horas. El tráfico de entrada es gratis.
...

Sheet Escenarios
A1: Escenarios de uso
A2: Mismo diseño, tres regímenes de operación
A4: Concepto | B4: A · Demo y ensayos | C4: B · MVP 24×7 | D4: C · Producción CITE | E4: Qué cambia
A5: Infraestructura Huawei | B5: =Detalle!$K$30-(Detalle!$K$5+Detalle!$K$8)*(1-Parametros!$B$7/Parametros!$B$6) | C5: =Detalle!$K$30 | D5: =Produccion!$K$31 | E5: A: ECS y RDS encendidos solo 80 h/mes; el almacenamiento se paga igual. C: hoja 'Produccion', costeada línea por línea (no es un multiplicador).
A6: LLM (ModelArts MaaS) | B6: ='LLM-MaaS'!$B$5*Usuarios!$B$16 | C6: ='LLM-MaaS'!$B$11 | D6: =('LLM-MaaS'!$B$5*Usuarios!$D$16+'LLM-MaaS'!$B$6*Usuarios!$D$17)*(1-'LLM-MaaS'!$B$9) | E6: Volúmenes definidos en la hoja 'Usuarios'. C: 500 premium + 2.000 gratuitos, con el ahorro de cache.
A7: Subtotal mensual (US$) | B7: =B5+B6 | C7: =C5+C6 | D7: =D5+D6
A8: Impuestos | B8: =B7*Parametros!$B$9 | C8: =C7*Parametros!$B$9 | D8: =D7*Parametros!$B$9 | E8: 0 % si se factura directo con Huawei Cloud International.
A9: TOTAL MENSUAL (US$) | B9: =B7+B8 | C9: =C7+C8 | D9: =D7+D8
A10: TOTAL MENSUAL (S/) | B10: =B9*Parametros!$B$8 | C10: =C9*Parametros!$B$8 | D10: =D9*Parametros!$B$8 | E10: Al tipo de cambio de la hoja 'Parámetros'.
A11: TOTAL ANUAL (US$) | B11: =B9*12 | C11: =C9*12 | D11: =D9*12 | E11: Sin descuento por compromiso.
A12: TOTAL ANUAL con compromiso (US$) | B12: =B9*12*(1-Parametros!$B$10) | C12: =C9*12*(1-Parametros!$B$10) | D12: =D9*12*(1-Parametros!$B$10) | E12: El descuento aplica a ECS y RDS prepagados. Aproximación conservadora: se aplica al total.
A14: Cuándo aplica cada escenario
A15: A · Demo y ensayos — hasta el CDR del 28 de agosto. Encender ECS y RDS solo para ensayar y presentar. Es el escenario correcto para las próximas cuatro semanas y el más barato con diferencia.
A16: B · MVP 24×7 — el CITE empieza a usarlo de verdad y el servicio debe estar disponible. Es la arquitectura de INFRA-HUAWEI-CLOUD.md tal cual.
A17: C · Producción CITE — tras la firma: fase 2 del ADR-003 (100-300 organizaciones). Base en alta disponibilidad, dos nodos de API con balanceador, NAT Gateway para el agente, CDN y WAF. Está costeado línea por línea en la hoja 'Produccion', con las palancas de recorte y lo que cuesta cada una.
A18: ATENCIÓN: el ADR-003 estimaba 'US$ 200-400/mes en fases 2-3' y el detalle de la hoja 'Produccion' sale por encima. La diferencia está casi entera en tres líneas que el ADR no costeó: RDS en alta disponibilidad, WAF y NAT Gateway. Conviene corregir esa cifra en el ADR antes de que el CITE la lea como compromiso.

Sheet Supuestos
A1: Supuestos, fuentes y verificación
A2: Cada estimación, de dónde sale y cómo comprobarla
A4: Tema | B4: Supuesto adoptado | C4: Justificación / cómo verificarlo
A5: Origen de los precios | B5: Estimaciones propias con rango mín/esperado/máx | C5: Huawei Cloud no publica lista de precios en HTML: solo el calculador (www.huaweicloud.com/intl/en-us/pricing/calculator.html), que es una aplicación JavaScript y no es citable ni automatizable. Se verificó también la página de precios de ECS y el PDF de facturación: explican los modos de cobro, no las tarifas. Por eso el libro trata el precio como ENTRADA.
A6: Región | B6: LA-Santiago | C6: Es la región de Huawei Cloud más cercana a Perú (~40-60 ms desde Lima). Con la base de datos dentro de la VPC, el RTT a Postgres baja a menos de 2 ms. Exige cuenta Huawei Cloud INTERNATIONAL.
A7: Tamaño del ECS | B7: 4 vCPU / 8 GB | C7: Lo fija bge-m3: ~2,3 GB residentes en RAM (documentado en adaptadores/modelo_embeddings.py); con PyTorch el proceso queda en 3,5-4,5 GB. Con 4 GB no arranca en condiciones. Sin GPU: el gate P03 se midió en CPU con p95 de 176 ms contra un techo de 2 s.
A8: Tamaño del RDS | B8: 2 vCPU / 4 GB, nodo único, 40 GB | C8: El estado de aplicación son kilobytes: ejecuciones, etapas, perfiles y el cache de respuestas LLM. 40 GB es el mínimo que admite el servicio. La alta disponibilidad primario/en espera duplica el importe y se difiere a producción.
A9: Almacenamiento de datos | B9: EVS 100 GB | C9: Medido en el repositorio: índice LanceDB 135 MB, snapshot 66 MB, PDFs 5,3 MB. Los 100 GB son margen para el snapshot siguiente, logs y PDFs acumulados.
A10: Tráfico saliente | B10: 30 GB al mes | C10: La SPA compilada pesa 173 KB y un informe PDF ~200 KB. 30 GB es holgado para demo y piloto; conviene revisarlo si el CITE publica el acceso a sus asociados.
A11: Horas de facturación | B11: 730 h/mes (24×7) · 80 h/mes en demo | C11: 730 = 365×24/12, la convención de facturación. El escenario de demo supone encender ECS y RDS solo para ensayos: el almacenamiento, la EIP y los backups se pagan igual.
A12: Descuento por compromiso | B12: 35 % | C12: Rango habitual del prepago anual (30-40 %) en ECS y RDS. VERIFICAR en el calculador cambiando el modo de facturación a Yearly/Monthly, y ajustar el parámetro.
A13: Impuestos | B13: 0 % | C13: Se asume facturación directa con Huawei Cloud International. Si se contrata a través de un socio peruano, poner 18 % de IGV en 'Parámetros' y todo el libro lo recoge.
A14: Coste del LLM | B14: US$ 0,21 por run premium | C14: DATO MEDIDO el 2026-08-02 y anotado en .env.example: entre 0,19 y 0,23 por run en frío, con tres de las cinco etapas sobre glm-5.2. Es el único bloque del presupuesto que no es estimación.
A15: Ahorro por cache | B15: 30 % | C15: El envoltorio etapa() cachea por (entrada, modelo, etapa, snapshot_version). En una demo con consultas repetidas el ahorro real es mayor; 30 % es conservador para uso mixto.
... A19: Riesgo de subestimación | B19: Peticiones de OBS y logs de LTS | C19: Son las dos líneas con confianza BAJA. En volúmenes de demo son céntimos; con uso real conviene medir un mes antes de comprometer una cifra anual.
