Workbook

Sheet Resumen
A1: AgroScout IA v3 — Presupuesto de desarrollo
A2: CITEagroindustrial Chavimochic · Alcance: plan TIERSV3 (11 semanas) + módulo de análisis regulatorio por mercado
A4: 1 · INVERSIÓN DE DESARROLLO (una sola vez)
A5: Concepto | B5: USD | C5: PEN | E5: Nota
A6: Horas del proyecto (2 personas + IA) | B6: =Esfuerzo!$G$60 | C6: — | E6: Incluye gestión y contingencia. El mismo alcance sin IA son 1.700 h.
A7: Costo interno de ejecución | B7: =Costo_Desarrollo!$D$23 | C7: =B7*Supuestos!$B$5 | E7: Mano de obra + licencias de IA + infraestructura de dev.
A8: Precio al cliente (sin IGV) | B8: =Costo_Desarrollo!$G$23 | C8: =B8*Supuestos!$B$5 | E8: Es el número que va a la propuesta. Se cobra en 5 hitos.
A9: Precio al cliente (con IGV) | B9: =Costo_Desarrollo!$G$25 | C9: =B9*Supuestos!$B$5
A10: Margen bruto | B10: =Costo_Desarrollo!$G$26 | C10: — | E10: Sobre el precio sin IGV.
A11: Plazo de entrega | B11: =Esfuerzo!$G$64 | C11: — | E11: El plan original pide 11 semanas con 3 personas.
A13: 2 · LO QUE APORTA LA IA
A14: Concepto | B14: Tradicional | C14: 2 pers. + IA | D14: Diferencia | E14: Nota
A15: Horas del proyecto | B15: =Esfuerzo!$E$60 | C15: =Esfuerzo!$G$60 | D15: =1-C15/B15 | E15: Reducción neta de esfuerzo.
A16: Costo interno (USD) | B16: =Costo_Desarrollo!$D$35 | C16: =Costo_Desarrollo!$D$10 | D16: =B16-C16 | E16: Solo mano de obra, para comparar peras con peras.
A17: Personas necesarias | B17: 3 | C17: 2 | D17: — | E17: 1 dev senior a tiempo completo + 1 data/QA a medio tiempo.
A18: Gasto en licencias de IA (todo el build) | B18: — | C18: =Herramientas_IA!$D$15*ROUNDUP(Esfuerzo!$G$64/4.33,0) | D18: =(B16-C16)/C18 | E18: Cada dólar gastado en IA evita esa cantidad de dólares de mano de obra.
A19: Infraestructura y observabilidad (USD/mes) | B19: =Infraestructura!$B$30 | C19: =Infraestructura!$C$30 | D19: =1-C19/B19 | E19: Huawei + Prometheus/Grafana autoalojados + Slack en vez de PagerDuty, frente al diseño sobre AWS de PLAN-MVP-v3 §10. Comparación línea a línea en la hoja Infraestructura.
A21: 3 · OPERACIÓN (a partir del go-live)
A22: Concepto | B22: USD/mes | C22: PEN/mes | D22: USD/año | E22: Nota
A23: Infraestructura Huawei (producción) | B23: =Infraestructura!$D$14 | C23: =B23*Supuestos!$B$5 | D23: =B23*12 | E23: 2 ECS, RDS con réplica, OBS, CBR, CDN.
A24: Licencias, APIs y observabilidad | B24: =Herramientas_IA!$D$14 | C24: =B24*Supuestos!$B$5 | D24: =B24*12 | E24: Bright Data, Tavily, Claude Code, Logfire.
A25: Mantenimiento y soporte | B25: =Supuestos!$B$50 | C25: =B25*Supuestos!$B$5 | D25: =B25*12 | E25: 0,25 FTE del dev senior.
A26: TOTAL FIJO | B26: =SUM(B23:B25) | C26: =B26*Supuestos!$B$5 | D26: =B26*12 | E26: El costo variable de LLM se suma aparte: menos de US$ 0,10 por consulta.
A27: Costo variable por consulta | B27: =Supuestos!$B$46 | C27: =B27*Supuestos!$B$5 | D27: — | E27: Promedio ponderado: 60 % gratuitas, 40 % premium, 30 % con análisis de aditivos.
A29: 4 · PROYECCIÓN A 36 MESES
A30: Indicador | B30: Conservador | C30: Base | D30: Optimista | E30: Nota
A31: Ingreso recurrente mes 12 (USD/mes) | B31: =Escenarios!$B$6 | C31: =Escenarios!$C$6 | D31: =Escenarios!$D$6
A32: Ingreso recurrente mes 36 (USD/mes) | B32: =Escenarios!$B$8 | C32: =Escenarios!$C$8 | D32: =Escenarios!$D$8
A33: Resultado acumulado 36 m (USD) | B33: =Escenarios!$B$10 | C33: =Escenarios!$C$10 | D33: =Escenarios!$D$10 | E33: Con el modelo de negocio elegido en Supuestos.
A34: Mes de equilibrio operativo | B34: =Escenarios!$B$12 | C34: =Escenarios!$C$12 | D34: =Escenarios!$D$12 | E34: Cuando la suscripción cubre infraestructura, soporte y LLM.
A35: Mes de recuperación de la inversión | B35: =Escenarios!$B$13 | C35: =Escenarios!$C$13 | D35: =Escenarios!$D$13
A38: 5 · CÓMO LEER ESTE LIBRO
A39: Supuestos | B39: Todo lo editable: tipo de cambio, tarifas, factores de IA, precios de plan, adopción.
A40: Esfuerzo | B40: Actividad por actividad, horas base contra horas con IA. Es el corazón del cálculo.
A41: Costo_Desarrollo | B41: Precio y costo por rol, más la comparación contra el equipo tradicional.
A42: Herramientas_IA | B42: Qué se paga en licencias y cuánto trabajo evita cada dólar.
A43: Infraestructura | B43: Huawei Cloud mes a mes y el ahorro frente al diseño original en AWS.
A44: Costo_LLM | B44: Costo por etapa y por volumen: el margen sobre el uso no baja del 95 %.
A45: Proyeccion_36m | B45: 36 meses de ingresos, costos y caja en tres escenarios.
A46: Escenarios | B46: Sensibilidad y riesgos cuantificados en horas y dólares.
...

Sheet Supuestos
A1: Supuestos y parámetros del modelo
A2: Todas las celdas color arena son editables: el resto del libro se recalcula solo.
A4: 1 · PARÁMETROS GENERALES
A5: Tipo de cambio USD → PEN | B5: 3.75 | D5: Referencial; ajustar al del contrato.
A6: IGV | B6: 0.18 | D6: Se muestra por separado; el precio base es sin IGV.
A7: Horas efectivas/semana — Dev Senior | B7: 34 | D7: 40 h nominales × 85 % de productividad real.
A8: Horas efectivas/semana — Data/QA | B8: 20 | D8: Medio tiempo (0,5 FTE).
A9: Semanas del plan original (equipo 3-4 pers.) | B9: 11 | D9: TIERSV3: S1–S11, ruta crítica sin paralelización.
A10: Modelo de negocio (1 = producto propio · 2 = contrato CITE) | B10: 2 | D10: 1: la inversión la absorbe Codeplai. 2: el CITE paga por hitos (hoja Hitos_Pago).
A12: 2 · TARIFAS POR ROL (USD/hora)
A13: Rol | B13: Costo | C13: Venta | D13: Nota
A14: Dev Senior Full-stack + IA | B14: 26 | C14: 48 | D14: Perfil que lleva el grueso del código asistido por Claude Code.
A15: Data / QA (medio tiempo) | B15: 16 | C15: 32 | D15: Pruebas, carga, ETL de apoyo y validación de datos.
A16: Especialista regulatorio | B16: 22 | C16: 42 | D16: Curación manual de Codex/GSFA. La IA no acelera esto.
A17: Dirección técnica / PM | B17: 32 | C17: 60 | D17: Coordinación, hitos, interlocución con el CITE.
A19: 3 · FACTORES DE ACELERACIÓN POR IA
A20: Tipo de tarea | B20: Factor | C20: Equivale a | D20: Justificación
A21: Código de aplicación | B21: 0.3 | C21: =IF(B21=0,"",1/B21) | D21: Andamiaje, contratos Pydantic, endpoints y UI generados y revisados.
A22: Integraciones / ETL / parsers | B22: 0.35 | C22: =IF(B22=0,"",1/B22) | D22: Parsers de eCFR/EUR-Lex/RASFF: la IA escribe, la sonda manda.
A23: Infraestructura / DevOps | B23: 0.6 | C23: =IF(B23=0,"",1/B23) | D23: Hay esperas reales (aprovisionamiento, DNS, TLS) que no se aceleran.
A24: Pruebas / QA / carga | B24: 0.4 | C24: =IF(B24=0,"",1/B24) | D24: Suites generadas a partir del contrato; el load test tarda lo que tarda.
A25: Curación manual de datos | B25: 0.95 | C25: =IF(B25=0,"",1/B25) | D25: Codex/GSFA se cura a mano: la FAO prohíbe el rastreo en su robots.txt.
A26: Documentación / capacitación | B26: 0.25 | C26: =IF(B26=0,"",1/B26) | D26: Runbooks y material de capacitación a partir del propio repo.
A28: 4 · SOBRECOSTES DE PROYECTO
A29: Gestión / PM (% sobre horas técnicas) | B29: 0.1 | D29: Se factura como rol propio a tarifa de dirección técnica.
A30: Contingencia (% sobre horas totales) | B30: 0.15 | D30: Colchón para reaperturas: Codex bloqueado, latencia de glm-5.2, anti-bot.
A31: Margen sobre costos directos de terceros | B31: 0.15 | D31: Se aplica a licencias e infraestructura reembolsadas al cliente.
A33: 5 · PRECIOS DE SUSCRIPCIÓN (USD/mes, sin IGV)
A34: Plan | B34: Precio/mes | C34: Consultas/mes | D34: Perfil
A35: Básico | B35: 29 | C35: 10 | D35: Mipyme / productor individual.
A36: Avanzado | B36: 99 | C36: 40 | D36: Cooperativa / agroexportadora: regulatorio + PDF.
A37: Institucional | B37: 800 | C37: 200 | D37: CITE Chavimochic y red ITP: panel, agregados, multiusuario.
A39: 6 · COSTO VARIABLE POR CONSULTA (USD)
A41: Run gratuito — etapas 1-3 | B41: 0.008 | D41: Medido: deepseek-v4-flash en E1/E2a + glm-4.7 en E3.
A42: Run premium — etapas 1-5 + agente comercial | B42: 0.21 | D42: Run premium en frío según INFRA-HUAWEI-CLOUD §8.
A43: Análisis regulatorio de aditivos (en frío) | B43: 0.05 | D43: ~4 aditivos × glm-5.2; en caliente el caché lo deja en 0.
A44: % de runs premium | B44: 0.4 | D44: El resto son gratuitos (paywall de etapas 4-5).
A45: % de runs con análisis de aditivos | B45: 0.3 | D45: Solo las filas del mapa comercial que el usuario abre.
A46: Costo promedio por consulta | B46: =(1-B44)*B41+B44*B42+B45*B43 | D46: Calculado. Es el número que mueve el costo variable de la proyección.
A48: 7 · OPERACIÓN Y ADOPCIÓN
...

Sheet Esfuerzo
A1: Esfuerzo por actividad — equipo tradicional vs. 2 personas + IA
A2: Horas base = lo que costaría el plan TIERSV3 con 3 personas. Horas con IA = horas base × factor de la hoja Supuestos.
A4: Bloque | B4: Actividad | C4: Tipo de tarea | D4: Rol | E4: Horas base | F4: Factor IA | G4: Horas con IA | H4: Horas ahorradas
A5: S1 | B5: VPC, Postgres replicado, balanceador y 2 nodos API | C5: Infraestructura / DevOps | D5: Dev Senior Full-stack + IA | E5: 40 | F5: =VLOOKUP(C5,Supuestos!$A$21:$B$26,2,FALSE) | G5: =E5*F5 | H5: =E5-G5
A6: S1 | B6: Observabilidad, object storage, CDN y TLS | C6: Infraestructura / DevOps | D6: Dev Senior Full-stack + IA | E6: 24 | F6: =VLOOKUP(C6,Supuestos!$A$21:$B$26,2,FALSE) | G6: =E6*F6 | H6: =E6-G6
A7: S1 | B7: Pruebas de restore y failover (P16) | C7: Pruebas / QA / carga | D7: Data / QA (medio tiempo) | E7: 16 | F7: =VLOOKUP(C7,Supuestos!$A$21:$B$26,2,FALSE) | G7: =E7*F7 | H7: =E7-G7
A8: S2 | B8: AgenteInvestigadorComercial (Pydantic AI + Tavily) | C8: Integraciones / ETL / parsers | D8: Dev Senior Full-stack + IA | E8: 40 | F8: =VLOOKUP(C8,Supuestos!$A$21:$B$26,2,FALSE) | G8: =E8*F8 | H8: =E8-G8
A9: S2 | B9: Cuarentena staging_agente + grounding check | C9: Código de aplicación | D9: Dev Senior Full-stack + IA | E9: 32 | F9: =VLOOKUP(C9,Supuestos!$A$21:$B$26,2,FALSE) | G9: =E9*F9 | H9: =E9-G9
A10: S2 | B10: Cascada N1→N2→N3, presupuestos y kill-switch | C10: Código de aplicación | D10: Dev Senior Full-stack + IA | E10: 24 | F10: =VLOOKUP(C10,Supuestos!$A$21:$B$26,2,FALSE) | G10: =E10*F10 | H10: =E10-G10
A11: S2 | B11: P11/P12/P13 + failover Tavily→Brave (P17) | C11: Pruebas / QA / carga | D11: Data / QA (medio tiempo) | E11: 24 | F11: =VLOOKUP(C11,Supuestos!$A$21:$B$26,2,FALSE) | G11: =E11*F11 | H11: =E11-G11
A12: S3 | B12: Cola procrastinate + worker + eventos_job | C12: Código de aplicación | D12: Dev Senior Full-stack + IA | E12: 32 | F12: =VLOOKUP(C12,Supuestos!$A$21:$B$26,2,FALSE) | G12: =E12*F12 | H12: =E12-G12
A13: S3 | B13: Etapa 6 (PDF) como job asíncrono con progreso | C13: Código de aplicación | D13: Dev Senior Full-stack + IA | E13: 16 | F13: =VLOOKUP(C13,Supuestos!$A$21:$B$26,2,FALSE) | G13: =E13*F13 | H13: =E13-G13
A14: S3 | B14: Motor de tendencias DuckDB particionado por trimestre | C14: Integraciones / ETL / parsers | D14: Dev Senior Full-stack + IA | E14: 40 | F14: =VLOOKUP(C14,Supuestos!$A$21:$B$26,2,FALSE) | G14: =E14*F14 | H14: =E14-G14
A15: S3 | B15: Taxonomía CITE v0.1 + anti-corruption layer | C15: Integraciones / ETL / parsers | D15: Dev Senior Full-stack + IA | E15: 16 | F15: =VLOOKUP(C15,Supuestos!$A$21:$B$26,2,FALSE) | G15: =E15*F15 | H15: =E15-G15
A16: S3 | B16: UI de promoción manual + P10 degradada | C16: Código de aplicación | D16: Dev Senior Full-stack + IA | E16: 16 | F16: =VLOOKUP(C16,Supuestos!$A$21:$B$26,2,FALSE) | G16: =E16*F16 | H16: =E16-G16
... A55: ADI | B55: T7 · Validador de honestidad y auditoría | C55: Pruebas / QA / carga | D55: Data / QA (medio tiempo) | E55: 24 | F55: =VLOOKUP(C55,Supuestos!$A$21:$B$26,2,FALSE) | G55: =E55*F55 | H55: =E55-G55
A56: SUBTOTAL TÉCNICO | E56: =SUM(E5:E55) | G56: =SUM(G5:G55) | H56: =SUM(H5:H55)
A57: Gestión / PM | B57: Coordinación, hitos y reporte al CITE | C57: — | D57: Dirección técnica / PM | E57: =E56*Supuestos!$B$29 | G57: =G56*Supuestos!$B$29 | H57: =E57-G57
A58: SUBTOTAL CON GESTIÓN | E58: =E56+E57 | G58: =G56+G57 | H58: =H56+H57
A59: Contingencia | B59: Reaperturas previstas en la hoja de riesgos | E59: =E58*Supuestos!$B$30 | G59: =G58*Supuestos!$B$30 | H59: =E59-G59
A60: TOTAL HORAS | E60: =E58+E59 | G60: =G58+G59 | H60: =H58+H59
A62: Reducción de esfuerzo por uso de IA | E62: =1-G60/E60
A63: Días-persona (8 h) — tradicional / con IA | E63: =E60/8 | G63: =G60/8
A64: Calendario con 2 personas (semanas) | G64: =G60/(Supuestos!$B$7+Supuestos!$B$8)
A65: Nota: el plan original necesita 11 semanas con 3 personas. Con 2 personas + IA el calendario apenas se alarga, pero las horas facturables caen a menos de la mitad.

Sheet Costo_Desarrollo
A1: Costo y precio del desarrollo
A2: Bloque A: escenario 2 personas + IA (el que se propone). Bloque B: el mismo alcance con equipo tradicional, como referencia.
A4: A · ESCENARIO PROPUESTO — 2 PERSONAS + IA (incluye contingencia)
A5: Rol | B5: Horas | C5: Costo USD/h | D5: Costo USD | E5: Costo PEN | F5: Venta USD/h | G5: Precio USD | H5: Precio PEN
A6: Dev Senior Full-stack + IA | B6: =SUMIF(Esfuerzo!$D$5:$D$55,$A6,Esfuerzo!$G$5:$G$55)*(1+Supuestos!$B$30) | C6: =Supuestos!$B$14 | D6: =B6*C6 | E6: =D6*Supuestos!$B$5 | F6: =Supuestos!$C$14 | G6: =B6*F6 | H6: =G6*Supuestos!$B$5
A7: Data / QA (medio tiempo) | B7: =SUMIF(Esfuerzo!$D$5:$D$55,$A7,Esfuerzo!$G$5:$G$55)*(1+Supuestos!$B$30) | C7: =Supuestos!$B$15 | D7: =B7*C7 | E7: =D7*Supuestos!$B$5 | F7: =Supuestos!$C$15 | G7: =B7*F7 | H7: =G7*Supuestos!$B$5
A8: Especialista regulatorio | B8: =SUMIF(Esfuerzo!$D$5:$D$55,$A8,Esfuerzo!$G$5:$G$55)*(1+Supuestos!$B$30) | C8: =Supuestos!$B$16 | D8: =B8*C8 | E8: =D8*Supuestos!$B$5 | F8: =Supuestos!$C$16 | G8: =B8*F8 | H8: =G8*Supuestos!$B$5
A9: Dirección técnica / PM | B9: =Esfuerzo!$G$57*(1+Supuestos!$B$30) | C9: =Supuestos!$B$17 | D9: =B9*C9 | E9: =D9*Supuestos!$B$5 | F9: =Supuestos!$C$17 | G9: =B9*F9 | H9: =G9*Supuestos!$B$5
A10: TOTAL MANO DE OBRA | B10: =SUM(B6:B9) | D10: =SUM(D6:D9) | E10: =SUM(E6:E9) | G10: =SUM(G6:G9) | H10: =SUM(H6:H9)
A12: A.2 · COSTOS DIRECTOS DEL PROYECTO
A13: Concepto | B13: Meses | C13: USD/mes | D13: Costo USD | E13: Costo PEN | F13: Margen | G13: Precio USD | H13: Precio PEN
A14: Licencias de IA y herramientas de desarrollo | B14: =ROUNDUP(Esfuerzo!$G$64/4.33,0) | C14: =Herramientas_IA!$D$13-Herramientas_IA!$D$16 | D14: =B14*C14 | E14: =D14*Supuestos!$B$5 | F14: =Supuestos!$B$31 | G14: =D14*(1+F14) | H14: =G14*Supuestos!$B$5
A15: Infraestructura de desarrollo y staging | B15: =ROUNDUP(Esfuerzo!$G$64/4.33,0) | C15: =Infraestructura!$C$14 | D15: =B15*C15 | E15: =D15*Supuestos!$B$5 | F15: =Supuestos!$B$31 | G15: =D15*(1+F15) | H15: =G15*Supuestos!$B$5
A16: Datos y APIs de terceros durante el build | B16: =ROUNDUP(Esfuerzo!$G$64/4.33,0) | C16: =Herramientas_IA!$D$16 | D16: =B16*C16 | E16: =D16*Supuestos!$B$5 | F16: =Supuestos!$B$31 | G16: =D16*(1+F16) | H16: =G16*Supuestos!$B$5
A17: TOTAL COSTOS DIRECTOS | D17: =SUM(D14:D16) | E17: =SUM(E14:E16) | G17: =SUM(G14:G16) | H17: =SUM(H14:H16)
A19: A.3 · TOTAL DEL PROYECTO
A20: Concepto | D20: Costo USD | E20: Costo PEN | G20: Precio USD | H20: Precio PEN
A21: Mano de obra | D21: =D10 | E21: =E10 | G21: =G10 | H21: =H10
A22: Costos directos | D22: =D17 | E22: =E17 | G22: =G17 | H22: =H17
A23: TOTAL SIN IGV | D23: =SUM(D21:D22) | E23: =SUM(E21:E22) | G23: =SUM(G21:G22) | H23: =SUM(H21:H22)
A24: IGV | G24: =G23*Supuestos!$B$6 | H24: =H23*Supuestos!$B$6
A25: TOTAL CON IGV | G25: =G23+G24 | H25: =H23+H24
A26: Margen bruto del proyecto | G26: =(G23-D23)/G23 | H26: =G23-D23
A29: B · REFERENCIA — MISMO ALCANCE CON EQUIPO TRADICIONAL (3 personas, sin IA)
A30: Rol | B30: Horas | C30: Costo USD/h | D30: Costo USD | E30: Costo PEN | F30: Venta USD/h | G30: Precio USD | H30: Precio PEN
A31: Dev Senior Full-stack + IA | B31: =SUMIF(Esfuerzo!$D$5:$D$55,$A31,Esfuerzo!$E$5:$E$55)*(1+Supuestos!$B$30) | C31: =Supuestos!$B$14 | D31: =B31*C31 | E31: =D31*Supuestos!$B$5 | F31: =Supuestos!$C$14 | G31: =B31*F31 | H31: =G31*Supuestos!$B$5
A32: Data / QA (medio tiempo) | B32: =SUMIF(Esfuerzo!$D$5:$D$55,$A32,Esfuerzo!$E$5:$E$55)*(1+Supuestos!$B$30) | C32: =Supuestos!$B$15 | D32: =B32*C32 | E32: =D32*Supuestos!$B$5 | F32: =Supuestos!$C$15 | G32: =B32*F32 | H32: =G32*Supuestos!$B$5
A33: Especialista regulatorio | B33: =SUMIF(Esfuerzo!$D$5:$D$55,$A33,Esfuerzo!$E$5:$E$55)*(1+Supuestos!$B$30) | C33: =Supuestos!$B$16 | D33: =B33*C33 | E33: =D33*Supuestos!$B$5 | F33: =Supuestos!$C$16 | G33: =B33*F33 | H33: =G33*Supuestos!$B$5
A34: Dirección técnica / PM | B34: =Esfuerzo!$E$57*(1+Supuestos!$B$30) | C34: =Supuestos!$B$17 | D34: =B34*C34 | E34: =D34*Supuestos!$B$5 | F34: =Supuestos!$C$17 | G34: =B34*F34 | H34: =G34*Supuestos!$B$5
A35: TOTAL MANO DE OBRA | B35: =SUM(B31:B34) | D35: =SUM(D31:D34) | E35: =SUM(E31:E34) | G35: =SUM(G31:G34) | H35: =SUM(H31:H34)
A37: B.2 · COMPARACIÓN
A38: Concepto | B38: Tradicional | C38: 2 pers. + IA | D38: Ahorro USD | E38: Ahorro %
A39: Horas de proyecto | B39: =B35 | C39: =B10 | D39: =B39-C39 | E39: =1-C39/B39
A40: Costo de mano de obra (USD) | B40: =D35 | C40: =D10 | D40: =B40-C40 | E40: =1-C40/B40
A41: Precio de venta equivalente (USD) | B41: =G35 | C41: =G10 | D41: =B41-C41 | E41: =1-C41/B41
A42: Calendario (semanas) | B42: =Supuestos!$B$9 | C42: =Esfuerzo!$G$64 | D42: =B42-C42 | E42: =IF(B42=0,0,1-C42/B42)
A44: La aceleración por IA no comprime el calendario (2 personas rinden casi lo mismo que 3 en tiempo), pero sí el costo: la misma entrega con menos de la mitad de horas facturables.

Sheet Herramientas_IA
A1: Licencias de IA, APIs y herramientas
A2: El gasto que sustituye horas de equipo. Se separa lo que solo corre durante el build de lo que sigue en operación.
A4: Concepto | B4: Categoría | C4: Unidades | D4: USD/mes | E4: En build | F4: En operación | G4: Nota
A5: Claude Code (plan Max 20x) | B5: IA de desarrollo | C5: 1 | D5: 200 | E5: Sí | F5: Sí | G5: El motor de la aceleración: 1 asiento para el dev senior.
A6: Claude Code (plan Pro) | B6: IA de desarrollo | C6: 1 | D6: 100 | E6: Sí | F6: No | G6: Asiento del perfil Data/QA durante el build.
A7: GitHub Team | B7: Desarrollo | C7: 2 | D7: 8 | E7: Sí | F7: Sí | G7: Repos privados, Actions y revisión de PR.
A8: Tavily (búsqueda del agente) | B8: API de datos | C8: 1 | D8: 50 | E8: Sí | F8: Sí | G8: Búsqueda web del AgenteInvestigadorComercial.
A9: Bright Data (Web Unlocker / Scraper) | B9: API de datos | C9: 1 | D9: 200 | E9: Sí | F9: Sí | G9: 5 tiendas anti-bot de N2. Pago por uso; el tope lo pone el kill-switch.
A10: Huawei ModelArts MaaS (dev/test) | B10: LLM | C10: 1 | D10: 40 | E10: Sí | F10: No | G10: Tokens quemados en pruebas y evaluaciones, no en producción.
A11: Logfire / Sentry | B11: Observabilidad | C11: 1 | D11: 29 | E11: Sí | F11: Sí | G11: Trazas de la app. Prometheus y Grafana van autoalojados: US$ 0.
A12: Dominio, TLS y correo transaccional | B12: Infra ligera | C12: 1 | D12: 8 | E12: Sí | F12: Sí | G12: TLS por Let's Encrypt.
A13: TOTAL EN BUILD (USD/mes) | D13: =SUMPRODUCT(($E$5:$E$12="Sí")*$C$5:$C$12*$D$5:$D$12)
A14: TOTAL EN OPERACIÓN (USD/mes) | D14: =SUMPRODUCT(($F$5:$F$12="Sí")*$C$5:$C$12*$D$5:$D$12)
A15: Solo IA de desarrollo (build) | D15: =SUMPRODUCT(($B$5:$B$12="IA de desarrollo")*$C$5:$C$12*$D$5:$D$12)
A16: Solo APIs de datos (build) | D16: =SUMPRODUCT(($B$5:$B$12="API de datos")*$C$5:$C$12*$D$5:$D$12)
A18: Retorno de las licencias de IA
A19: Costo de IA durante todo el build (USD) | D19: =$D$15*ROUNDUP(Esfuerzo!$G$64/4.33,0)
A20: Horas de trabajo que evita (h) | D20: =Esfuerzo!$H$60
A21: Valor de esas horas a tarifa de costo (USD) | D21: =Esfuerzo!$H$60*Supuestos!$B$14
A22: Retorno de la inversión en IA | D22: =D21/D19

Sheet Infraestructura
A1: Infraestructura — Huawei Cloud LA-Santiago
A2: Dimensionada por bge-m3 (2,3 GB en RAM), no por el tráfico. Precios con compromiso anual.
A4: Recurso | B4: Especificación | C4: USD/mes dev | D4: USD/mes producción | E4: Nota
A5: ECS API | B5: s7n.xlarge.2 · 4 vCPU / 8 GB × 2 en prod | C5: 60 | D5: 120 | E5: 8 GB es el suelo: el modelo de embeddings ocupa 2,3 GB y --workers 1.
A6: ELB | B6: Balanceador compartido | C6: 0 | D6: 25 | E6: Solo en producción; en dev se entra directo al ECS.
A7: RDS PostgreSQL | B7: rds.pg.n1.large.2 + réplica de lectura | C7: 35 | D7: 130 | E7: En red privada, sin acceso público. RTT < 2 ms desde el ECS.
A8: EVS | B8: SSD 100 GB en /data | C8: 12 | D8: 24 | E8: PDFs de trabajo, índice LanceDB y logs.
A9: EIP y tráfico | B9: Pago por tráfico | C9: 8 | D9: 20 | E9: Uso bajo; el tráfico pesado va por CDN.
A10: OBS | B10: Object storage 100 GB | C10: 2 | D10: 6 | E10: Fuente de verdad de snapshot, índice, PDFs y pesos del modelo.
A11: CBR | B11: Backup con retención 7 días + PITR | C11: 8 | D11: 16 | E11: Sustituye el pg_dump manual.
A12: LTS + CES + SMN | B12: Logs, métricas y alarmas | C12: 3 | D12: 8 | E12: 4 alarmas: CPU, memoria, disco e instancia caída.
A13: CDN | B13: Cloudflare (plan Pro) | C13: 0 | D13: 20 | E13: Sirve datasets/ y PDFs; descarga al ECS.
A14: TOTAL HUAWEI (USD/mes) | C14: =SUM(C5:C13) | D14: =SUM(D5:D13)
A16: COSTO OPERATIVO MENSUAL COMPLETO
A17: Infraestructura Huawei (producción) | D17: =D14 | E17: Suma de la tabla de arriba.
A18: Licencias, APIs y observabilidad | D18: =Herramientas_IA!$D$14 | E18: De la hoja Herramientas_IA, solo lo marcado 'en operación'.
A19: Mantenimiento y soporte | D19: =Supuestos!$B$50 | E19: 0,25 FTE del dev senior.
A20: TOTAL FIJO MENSUAL (USD) | D20: =SUM(D17:D19) | E20: No incluye el costo variable de LLM (hoja Costo_LLM).
A21: TOTAL FIJO MENSUAL (PEN) | D21: =D20*Supuestos!$B$5
A23: AHORRO FRENTE AL DISEÑO ORIGINAL DEL PLAN v3
A24: Concepto | B24: Plan v3 original (AWS) | C24: Esta propuesta (Huawei) | D24: Ahorro USD/mes | E24: Cómo
A25: Compute | B25: 350 | C25: =D5 | D25: =B25-C25 | E25: 2 ECS en Huawei en vez de 2 t4g.xlarge en AWS.
A26: Base de datos | B26: 250 | C26: =D7 | D26: =B26-C26 | E26: RDS con una réplica, no dos, y sin multi-AZ.
A27: Object storage y CDN | B27: 125 | C27: =D10+D13 | D27: =B27-C27 | E27: OBS + Cloudflare Pro.
A28: Observabilidad | B28: 150 | C28: 0 | D28: =B28-C28 | E28: Prometheus y Grafana autoalojados en el ECS existente.
A29: Alertas (PagerDuty) | B29: 75 | C29: 0 | D29: =B29-C29 | E29: Webhook a Slack + alarmas CES. Cero licencia.
A30: TOTAL | B30: =SUM(B25:B29) | C30: =SUM(C25:C29) | D30: =SUM(D25:D29)
A31: Ahorro anual | D31: =D30*12

Sheet Costo_LLM
A1: Costo variable por consulta
A2: El único costo que escala con el uso. Medido sobre el reparto de modelos por etapa.
A4: Etapa | B4: Modelo | C4: Tokens ent. | D4: Tokens sal. | E4: USD/run | F4: Plan | G4: Nota
A5: 1 · Interpretar insumo | B5: deepseek-v4-flash | C5: 400 | D5: 230 | E5: 0.00021 | F5: Gratuito | G5: Cacheado: la 2.ª consulta del mismo insumo cuesta 0.
A6: 2a · Match de productos | B6: deepseek-v4-flash | C6: 400 | D6: 230 | E6: 0.00021 | F6: Gratuito | G6: Búsqueda vectorial local; el LLM solo reordena.
A7: 2b · Mapa comercial | B7: — (sin LLM) | C7: 0 | D7: 0 | E7: 0 | F7: Gratuito | G7: Lee del índice y del catálogo comercial.
A8: 3 · Insight de mercado | B8: glm-4.7 | C8: 860 | D8: 680 | E8: 0.0036 | F8: Gratuito | G8: Redacta a partir de datos ya verificados.
A9: 4 · Hipótesis de formulación | B9: glm-5.2 | C9: 1200 | D9: 900 | E9: 0.01 | F9: Premium | G9: Detrás del paywall.
A10: 5 · Verificación regulatoria | B10: glm-5.2 | C10: 1400 | D10: 900 | E10: 0.01 | F10: Premium | G10: Detrás del paywall.
A11: Agente comercial (N3) | B11: glm-5.2 + Tavily | C11: 3000 | D11: 1200 | E11: 0.185 | F11: Premium | G11: Lo caro: búsqueda web + lectura + grounding check.
A12: Análisis de aditivos (por aditivo) | B12: glm-5.2 + eCFR | C12: 2500 | D12: 800 | E12: 0.0125 | F12: Premium | G12: En caliente el caché lo deja en 0; ~4 aditivos por producto.
A13: Run gratuito (etapas 1-3) | E13: =SUMIF($F$5:$F$12,"Gratuito",$E$5:$E$12)
A14: Run premium completo (1-5 + agente) | E14: =SUM($E$5:$E$12)-$E$12+$E$12*4
A15: Costo promedio ponderado (hoja Supuestos) | E15: =Supuestos!$B$46
A17: PROYECCIÓN POR VOLUMEN
A18: Consultas/mes | B18: Costo LLM/mes USD | C18: Costo LLM/mes PEN | D18: Costo anual USD | E18: % del OPEX fijo | F18: Ingreso equivalente* | G18: Margen sobre el variable
A19: 100 | B19: =A19*Supuestos!$B$46 | C19: =B19*Supuestos!$B$5 | D19: =B19*12 | E19: =B19/Infraestructura!$D$20 | F19: =A19/Supuestos!$C$36*Supuestos!$B$36 | G19: =1-B19/F19
A20: 250 | B20: =A20*Supuestos!$B$46 | C20: =B20*Supuestos!$B$5 | D20: =B20*12 | E20: =B20/Infraestructura!$D$20 | F20: =A20/Supuestos!$C$36*Supuestos!$B$36 | G20: =1-B20/F20
A21: 500 | B21: =A21*Supuestos!$B$46 | C21: =B21*Supuestos!$B$5 | D21: =B21*12 | E21: =B21/Infraestructura!$D$20 | F21: =A21/Supuestos!$C$36*Supuestos!$B$36 | G21: =1-B21/F21
A22: 1000 | B22: =A22*Supuestos!$B$46 | C22: =B22*Supuestos!$B$5 | D22: =B22*12 | E22: =B22/Infraestructura!$D$20 | F22: =A22/Supuestos!$C$36*Supuestos!$B$36 | G22: =1-B22/F22
A23: 2500 | B23: =A23*Supuestos!$B$46 | C23: =B23*Supuestos!$B$5 | D23: =B23*12 | E23: =B23/Infraestructura!$D$20 | F23: =A23/Supuestos!$C$36*Supuestos!$B$36 | G23: =1-B23/F23
A24: 5000 | B24: =A24*Supuestos!$B$46 | C24: =B24*Supuestos!$B$5 | D24: =B24*12 | E24: =B24/Infraestructura!$D$20 | F24: =A24/Supuestos!$C$36*Supuestos!$B$36 | G24: =1-B24/F24
A25: 10000 | B25: =A25*Supuestos!$B$46 | C25: =B25*Supuestos!$B$5 | D25: =B25*12 | E25: =B25/Infraestructura!$D$20 | F25: =A25/Supuestos!$C$36*Supuestos!$B$36 | G25: =1-B25/F25
A27: * Ingreso si ese volumen se sirviera íntegramente con planes Avanzado. Sirve para ver que el costo variable nunca es el problema: el margen sobre el uso se mantiene por encima del 95 %.

Sheet Proyeccion_36m
A1: Proyección financiera a 36 meses
A2: Tres escenarios de adopción sobre la misma curva base. El desarrollo ocupa los primeros meses.
R3: Resultado solo de operación (sin desarrollo ni cobros de hito) — es lo que fija el punto de equilibrio
A4: Mes | B4: Fase | C4: Básico | D4: Avanz. | E4: Instit. | F4: Consultas | G4: Ingresos | H4: Costo LLM | I4: OPEX fijo | J4: Desarrollo | K4: Cobros hito | L4: Resultado | M4: Acumulado | N4: Result. cons. | O4: Acum. cons. | P4: Result. opt. | Q4: Acum. opt. | R4: Oper. base | S4: Oper. cons. | T4: Oper. opt.
A5: 1 | B5: Desarrollo | C5: 0 | D5: 0 | E5: 0 | F5: =C5*Supuestos!$C$35+D5*Supuestos!$C$36+E5*Supuestos!$C$37 | G5: =(C5*Supuestos!$B$35+D5*Supuestos!$B$36+E5*Supuestos!$B$37)*Supuestos!$B$52 | H5: =F5*Supuestos!$B$46*Supuestos!$B$52 | I5: =IF(A5<=3,0,Infraestructura!$D$20) | J5: =-Costo_Desarrollo!$D$23*0.35 | K5: =IF(Supuestos!$B$10=2,Costo_Desarrollo!$G$23*0.3,0) | L5: =G5-H5-I5+J5+K5 | M5: =L5 | N5: =G5/Supuestos!$B$52*Supuestos!$B$51-F5*Supuestos!$B$46*Supuestos!$B$51-I5+J5+K5 | O5: =N5 | P5: =G5/Supuestos!$B$52*Supuestos!$B$53-F5*Supuestos!$B$46*Supuestos!$B$53-I5+J5+K5 | Q5: =P5 | R5: =G5-H5-I5 | S5: =G5/Supuestos!$B$52*Supuestos!$B$51-F5*Supuestos!$B$46*Supuestos!$B$51-I5 | T5: =G5/Supuestos!$B$52*Supuestos!$B$53-F5*Supuestos!$B$46*Supuestos!$B$53-I5 | U5: =IF(AND(A5>4,S5>0),1,0) | V5: =IF(AND(A5>4,R5>0),1,0) | W5: =IF(AND(A5>4,T5>0),1,0) | X5: =IF(AND(A5>4,O5>0),1,0) | Y5: =IF(AND(A5>4,M5>0),1,0) | Z5: =IF(AND(A5>4,Q5>0),1,0)
A6: 2 | B6: Desarrollo | C6: 0 | D6: 0 | E6: 0 | F6: =C6*Supuestos!$C$35+D6*Supuestos!$C$36+E6*Supuestos!$C$37 | G6: =(C6*Supuestos!$B$35+D6*Supuestos!$B$36+E6*Supuestos!$B$37)*Supuestos!$B$52 | H6: =F6*Supuestos!$B$46*Supuestos!$B$52 | I6: =IF(A6<=3,0,Infraestructura!$D$20) | J6: =-Costo_Desarrollo!$D$23*0.35 | K6: =IF(Supuestos!$B$10=2,Costo_Desarrollo!$G$23*0.25,0) | L6: =G6-H6-I6+J6+K6 | M6: =M5+L6 | N6: =G6/Supuestos!$B$52*Supuestos!$B$51-F6*Supuestos!$B$46*Supuestos!$B$51-I6+J6+K6 | O6: =O5+N6 | P6: =G6/Supuestos!$B$52*Supuestos!$B$53-F6*Supuestos!$B$46*Supuestos!$B$53-I6+J6+K6 | Q6: =Q5+P6 | R6: =G6-H6-I6 | S6: =G6/Supuestos!$B$52*Supuestos!$B$51-F6*Supuestos!$B$46*Supuestos!$B$51-I6 | T6: =G6/Supuestos!$B$52*Supuestos!$B$53-F6*Supuestos!$B$46*Supuestos!$B$53-I6 | U6: =IF(AND(A6>4,S6>0),1,0) | V6: =IF(AND(A6>4,R6>0),1,0) | W6: =IF(AND(A6>4,T6>0),1,0) | X6: =IF(AND(A6>4,O6>0),1,0) | Y6: =IF(AND(A6>4,M6>0),1,0) | Z6: =IF(AND(A6>4,Q6>0),1,0)
A7: 3 | B7: Desarrollo | C7: 0 | D7: 0 | E7: 0 | F7: =C7*Supuestos!$C$35+D7*Supuestos!$C$36+E7*Supuestos!$C$37 | G7: =(C7*Supuestos!$B$35+D7*Supuestos!$B$36+E7*Supuestos!$B$37)*Supuestos!$B$52 | H7: =F7*Supuestos!$B$46*Supuestos!$B$52 | I7: =IF(A7<=3,0,Infraestructura!$D$20) | J7: =-Costo_Desarrollo!$D$23*0.3 | K7: =IF(Supuestos!$B$10=2,Costo_Desarrollo!$G$23*0.25,0) | L7: =G7-H7-I7+J7+K7 | M7: =M6+L7 | N7: =G7/Supuestos!$B$52*Supuestos!$B$51-F7*Supuestos!$B$46*Supuestos!$B$51-I7+J7+K7 | O7: =O6+N7 | P7: =G7/Supuestos!$B$52*Supuestos!$B$53-F7*Supuestos!$B$46*Supuestos!$B$53-I7+J7+K7 | Q7: =Q6+P7 | R7: =G7-H7-I7 | S7: =G7/Supuestos!$B$52*Supuestos!$B$51-F7*Supuestos!$B$46*Supuestos!$B$51-I7 | T7: =G7/Supuestos!$B$52*Supuestos!$B$53-F7*Supuestos!$B$46*Supuestos!$B$53-I7 | U7: =IF(AND(A7>4,S7>0),1,0) | V7: =IF(AND(A7>4,R7>0),1,0) | W7: =IF(AND(A7>4,T7>0),1,0) | X7: =IF(AND(A7>4,O7>0),1,0) | Y7: =IF(AND(A7>4,M7>0),1,0) | Z7: =IF(AND(A7>4,Q7>0),1,0)
A8: 4 | B8: Go-live | C8: 5 | D8: 2 | E8: 1 | F8: =C8*Supuestos!$C$35+D8*Supuestos!$C$36+E8*Supuestos!$C$37 | G8: =(C8*Supuestos!$B$35+D8*Supuestos!$B$36+E8*Supuestos!$B$37)*Supuestos!$B$52 | H8: =F8*Supuestos!$B$46*Supuestos!$B$52 | I8: =IF(A8<=3,0,Infraestructura!$D$20) | J8: =-Costo_Desarrollo!$D$23*0 | K8: =IF(Supuestos!$B$10=2,Costo_Desarrollo!$G$23*0.2,0) | L8: =G8-H8-I8+J8+K8 | M8: =M7+L8 | N8: =G8/Supuestos!$B$52*Supuestos!$B$51-F8*Supuestos!$B$46*Supuestos!$B$51-I8+J8+K8 | O8: =O7+N8 | P8: =G8/Supuestos!$B$52*Supuestos!$B$53-F8*Supuestos!$B$46*Supuestos!$B$53-I8+J8+K8 | Q8: =Q7+P8 | R8: =G8-H8-I8 | S8: =G8/Supuestos!$B$52*Supuestos!$B$51-F8*Supuestos!$B$46*Supuestos!$B$51-I8 | T8: =G8/Supuestos!$B$52*Supuestos!$B$53-F8*Supuestos!$B$46*Supuestos!$B$53-I8 | U8: =IF(AND(A8>4,S8>0),1,0) | V8: =IF(AND(A8>4,R8>0),1,0) | W8: =IF(AND(A8>4,T8>0),1,0) | X8: =IF(AND(A8>4,O8>0),1,0) | Y8: =IF(AND(A8>4,M8>0),1,0) | Z8: =IF(AND(A8>4,Q8>0),1,0)
A9: 5 | B9: Operación | C9: 7 | D9: 3 | E9: 1 | F9: =C9*Supuestos!$C$35+D9*Supuestos!$C$36+E9*Supuestos!$C$37 | G9: =(C9*Supuestos!$B$35+D9*Supuestos!$B$36+E9*Supuestos!$B$37)*Supuestos!$B$52 | H9: =F9*Supuestos!$B$46*Supuestos!$B$52 | I9: =IF(A9<=3,0,Infraestructura!$D$20) | J9: =-Costo_Desarrollo!$D$23*0 | K9: =IF(Supuestos!$B$10=2,Costo_Desarrollo!$G$23*0,0) | L9: =G9-H9-I9+J9+K9 | M9: =M8+L9 | N9: =G9/Supuestos!$B$52*Supuestos!$B$51-F9*Supuestos!$B$46*Supuestos!$B$51-I9+J9+K9 | O9: =O8+N9 | P9: =G9/Supuestos!$B$52*Supuestos!$B$53-F9*Supuestos!$B$46*Supuestos!$B$53-I9+J9+K9 | Q9: =Q8+P9 | R9: =G9-H9-I9 | S9: =G9/Supuestos!$B$52*Supuestos!$B$51-F9*Supuestos!$B$46*Supuestos!$B$51-I9 | T9: =G9/Supuestos!$B$52*Supuestos!$B$53-F9*Supuestos!$B$46*Supuestos!$B$53-I9 | U9: =IF(AND(A9>4,S9>0),1,0) | V9: =IF(AND(A9>4,R9>0),1,0) | W9: =IF(AND(A9>4,T9>0),1,0) | X9: =IF(AND(A9>4,O9>0),1,0) | Y9: =IF(AND(A9>4,M9>0),1,0) | Z9: =IF(AND(A9>4,Q9>0),1,0)
A10: 6 | B10: Operación | C10: 10 | D10: 4 | E10: 1 | F10: =C10*Supuestos!$C$35+D10*Supuestos!$C$36+E10*Supuestos!$C$37 | G10: =(C10*Supuestos!$B$35+D10*Supuestos!$B$36+E10*Supuestos!$B$37)*Supuestos!$B$52 | H10: =F10*Supuestos!$B$46*Supuestos!$B$52 | I10: =IF(A10<=3,0,Infraestructura!$D$20) | J10: =-Costo_Desarrollo!$D$23*0 | K10: =IF(Supuestos!$B$10=2,Costo_Desarrollo!$G$23*0,0) | L10: =G10-H10-I10+J10+K10 | M10: =M9+L10 | N10: =G10/Supuestos!$B$52*Supuestos!$B$51-F10*Supuestos!$B$46*Supuestos!$B$51-I10+J10+K10 | O10: =O9+N10 | P10: =G10/Supuestos!$B$52*Supuestos!$B$53-F10*Supuestos!$B$46*Supuestos!$B$53-I10+J10+K10 | Q10: =Q9+P10 | R10: =G10-H10-I10 | S10: =G10/Supuestos!$B$52*Supuestos!$B$51-F10*Supuestos!$B$46*Supuestos!$B$51-I10 | T10: =G10/Supuestos!$B$52*Supuestos!$B$53-F10*Supuestos!$B$46*Supuestos!$B$53-I10 | U10: =IF(AND(A10>4,S10>0),1,0) | V10: =IF(AND(A10>4,R10>0),1,0) | W10: =IF(AND(A10>4,T10>0),1,0) | X10: =IF(AND(A10>4,O10>0),1,0) | Y10: =IF(AND(A10>4,M10>0),1,0) | Z10: =IF(AND(A10>4,Q10>0),1,0)
A11: 7 | B11: Operación | C11: 12 | D11: 5 | E11: 1 | F11: =C11*Supuestos!$C$35+D11*Supuestos!$C$36+E11*Supuestos!$C$37 | G11: =(C11*Supuestos!$B$35+D11*Supuestos!$B$36+E11*Supuestos!$B$37)*Supuestos!$B$52 | H11: =F11*Supuestos!$B$46*Supuestos!$B$52 | I11: =IF(A11<=3,0,Infraestructura!$D$20) | J11: =-Costo_Desarrollo!$D$23*0 | K11: =IF(Supuestos!$B$10=2,Costo_Desarrollo!$G$23*0,0) | L11: =G11-H11-I11+J11+K11 | M11: =M10+L11 | N11: =G11/Supuestos!$B$52*Supuestos!$B$51-F11*Supuestos!$B$46*Supuestos!$B$51-I11+J11+K11 | O11: =O10+N11 | P11: =G11/Supuestos!$B$52*Supuestos!$B$53-F11*Supuestos!$B$46*Supuestos!$B$53-I11+J11+K11 | Q11: =Q10+P11 | R11: =G11-H11-I11 | S11: =G11/Supuestos!$B$52*Supuestos!$B$51-F11*Supuestos!$B$46*Supuestos!$B$51-I11 | T11: =G11/Supuestos!$B$52*Supuestos!$B$53-F11*Supuestos!$B$46*Supuestos!$B$53-I11 | U11: =IF(AND(A11>4,S11>0),1,0) | V11: =IF(AND(A11>4,R11>0),1,0) | W11: =IF(AND(A11>4,T11>0),1,0) | X11: =IF(AND(A11>4,O11>0),1,0) | Y11: =IF(AND(A11>4,M11>0),1,0) | Z11: =IF(AND(A11>4,Q11>0),1,0)
A12: 8 | B12: Operación | C12: 15 | D12: 6 | E12: 1 | F12: =C12*Supuestos!$C$35+D12*Supuestos!$C$36+E12*Supuestos!$C$37 | G12: =(C12*Supuestos!$B$35+D12*Supuestos!$B$36+E12*Supuestos!$B$37)*Supuestos!$B$52 | H12: =F12*Supuestos!$B$46*Supuestos!$B$52 | I12: =IF(A12<=3,0,Infraestructura!$D$20) | J12: =-Costo_Desarrollo!$D$23*0 | K12: =IF(Supuestos!$B$10=2,Costo_Desarrollo!$G$23*0,0) | L12: =G12-H12-I12+J12+K12 | M12: =M11+L12 | N12: =G12/Supuestos!$B$52*Supuestos!$B$51-F12*Supuestos!$B$46*Supuestos!$B$51-I12+J12+K12 | O12: =O11+N12 | P12: =G12/Supuestos!$B$52*Supuestos!$B$53-F12*Supuestos!$B$46*Supuestos!$B$53-I12+J12+K12 | Q12: =Q11+P12 | R12: =G12-H12-I12 | S12: =G12/Supuestos!$B$52*Supuestos!$B$51-F12*Supuestos!$B$46*Supuestos!$B$51-I12 | T12: =G12/Supuestos!$B$52*Supuestos!$B$53-F12*Supuestos!$B$46*Supuestos!$B$53-I12 | U12: =IF(AND(A12>4,S12>0),1,0) | V12: =IF(AND(A12>4,R12>0),1,0) | W12: =IF(AND(A12>4,T12>0),1,0) | X12: =IF(AND(A12>4,O12>0),1,0) | Y12: =IF(AND(A12>4,M12>0),1,0) | Z12: =IF(AND(A12>4,Q12>0),1,0)
A13: 9 | B13: Operación | C13: 17 | D13: 7 | E13: 1 | F13: =C13*Supuestos!$C$35+D13*Supuestos!$C$36+E13*Supuestos!$C$37 | G13: =(C13*Supuestos!$B$35+D13*Supuestos!$B$36+E13*Supuestos!$B$37)*Supuestos!$B$52 | H13: =F13*Supuestos!$B$46*Supuestos!$B$52 | I13: =IF(A13<=3,0,Infraestructura!$D$20) | J13: =-Costo_Desarrollo!$D$23*0 | K13: =IF(Supuestos!$B$10=2,Costo_Desarrollo!$G$23*0,0) | L13: =G13-H13-I13+J13+K13 | M13: =M12+L13 | N13: =G13/Supuestos!$B$52*Supuestos!$B$51-F13*Supuestos!$B$46*Supuestos!$B$51-I13+J13+K13 | O13: =O12+N13 | P13: =G13/Supuestos!$B$52*Supuestos!$B$53-F13*Supuestos!$B$46*Supuestos!$B$53-I13+J13+K13 | Q13: =Q12+P13 | R13: =G13-H13-I13 | S13: =G13/Supuestos!$B$52*Supuestos!$B$51-F13*Supuestos!$B$46*Supuestos!$B$51-I13 | T13: =G13/Supuestos!$B$52*Supuestos!$B$53-F13*Supuestos!$B$46*Supuestos!$B$53-I13 | U13: =IF(AND(A13>4,S13>0),1,0) | V13: =IF(AND(A13>4,R13>0),1,0) | W13: =IF(AND(A13>4,T13>0),1,0) | X13: =IF(AND(A13>4,O13>0),1,0) | Y13: =IF(AND(A13>4,M13>0),1,0) | Z13: =IF(AND(A13>4,Q13>0),1,0)
A14: 10 | B14: Operación | C14: 19 | D14: 8 | E14: 1 | F14: =C14*Supuestos!$C$35+D14*Supuestos!$C$36+E14*Supuestos!$C$37 | G14: =(C14*Supuestos!$B$35+D14*Supuestos!$B$36+E14*Supuestos!$B$37)*Supuestos!$B$52 | H14: =F14*Supuestos!$B$46*Supuestos!$B$52 | I14: =IF(A14<=3,0,Infraestructura!$D$20) | J14: =-Costo_Desarrollo!$D$23*0 | K14: =IF(Supuestos!$B$10=2,Costo_Desarrollo!$G$23*0,0) | L14: =G14-H14-I14+J14+K14 | M14: =M13+L14 | N14: =G14/Supuestos!$B$52*Supuestos!$B$51-F14*Supuestos!$B$46*Supuestos!$B$51-I14+J14+K14 | O14: =O13+N14 | P14: =G14/Supuestos!$B$52*Supuestos!$B$53-F14*Supuestos!$B$46*Supuestos!$B$53-I14+J14+K14 | Q14: =Q13+P14 | R14: =G14-H14-I14 | S14: =G14/Supuestos!$B$52*Supuestos!$B$51-F14*Supuestos!$B$46*Supuestos!$B$51-I14 | T14: =G14/Supuestos!$B$52*Supuestos!$B$53-F14*Supuestos!$B$46*Supuestos!$B$53-I14 | U14: =IF(AND(A14>4,S14>0),1,0) | V14: =IF(AND(A14>4,R14>0),1,0) | W14: =IF(AND(A14>4,T14>0),1,0) | X14: =IF(AND(A14>4,O14>0),1,0) | Y14: =IF(AND(A14>4,M14>0),1,0) | Z14: =IF(AND(A14>4,Q14>0),1,0)
A15: 11 | B15: Operación | C15: 22 | D15: 9 | E15: 1 | F15: =C15*Supuestos!$C$35+D15*Supuestos!$C$36+E15*Supuestos!$C$37 | G15: =(C15*Supuestos!$B$35+D15*Supuestos!$B$36+E15*Supuestos!$B$37)*Supuestos!$B$52 | H15: =F15*Supuestos!$B$46*Supuestos!$B$52 | I15: =IF(A15<=3,0,Infraestructura!$D$20) | J15: =-Costo_Desarrollo!$D$23*0 | K15: =IF(Supuestos!$B$10=2,Costo_Desarrollo!$G$23*0,0) | L15: =G15-H15-I15+J15+K15 | M15: =M14+L15 | N15: =G15/Supuestos!$B$52*Supuestos!$B$51-F15*Supuestos!$B$46*Supuestos!$B$51-I15+J15+K15 | O15: =O14+N15 | P15: =G15/Supuestos!$B$52*Supuestos!$B$53-F15*Supuestos!$B$46*Supuestos!$B$53-I15+J15+K15 | Q15: =Q14+P15 | R15: =G15-H15-I15 | S15: =G15/Supuestos!$B$52*Supuestos!$B$51-F15*Supuestos!$B$46*Supuestos!$B$51-I15 | T15: =G15/Supuestos!$B$52*Supuestos!$B$53-F15*Supuestos!$B$46*Supuestos!$B$53-I15 | U15: =IF(AND(A15>4,S15>0),1,0) | V15: =IF(AND(A15>4,R15>0),1,0) | W15: =IF(AND(A15>4,T15>0),1,0) | X15: =IF(AND(A15>4,O15>0),1,0) | Y15: =IF(AND(A15>4,M15>0),1,0) | Z15: =IF(AND(A15>4,Q15>0),1,0)
A16: 12 | B16: Operación | C16: 24 | D16: 10 | E16: 1 | F16: =C16*Supuestos!$C$35+D16*Supuestos!$C$36+E16*Supuestos!$C$37 | G16: =(C16*Supuestos!$B$35+D16*Supuestos!$B$36+E16*Supuestos!$B$37)*Supuestos!$B$52 | H16: =F16*Supuestos!$B$46*Supuestos!$B$52 | I16: =IF(A16<=3,0,Infraestructura!$D$20) | J16: =-Costo_Desarrollo!$D$23*0 | K16: =IF(Supuestos!$B$10=2,Costo_Desarrollo!$G$23*0,0) | L16: =G16-H16-I16+J16+K16 | M16: =M15+L16 | N16: =G16/Supuestos!$B$52*Supuestos!$B$51-F16*Supuestos!$B$46*Supuestos!$B$51-I16+J16+K16 | O16: =O15+N16 | P16: =G16/Supuestos!$B$52*Supuestos!$B$53-F16*Supuestos!$B$46*Supuestos!$B$53-I16+J16+K16 | Q16: =Q15+P16 | R16: =G16-H16-I16 | S16: =G16/Supuestos!$B$52*Supuestos!$B$51-F16*Supuestos!$B$46*Supuestos!$B$51-I16 | T16: =G16/Supuestos!$B$52*Supuestos!$B$53-F16*Supuestos!$B$46*Supuestos!$B$53-I16 | U16: =IF(AND(A16>4,S16>0),1,0) | V16: =IF(AND(A16>4,R16>0),1,0) | W16: =IF(AND(A16>4,T16>0),1,0) | X16: =IF(AND(A16>4,O16>0),1,0) | Y16: =IF(AND(A16>4,M16>0),1,0) | Z16: =IF(AND(A16>4,Q16>0),1,0)
A17: 13 | B17: Operación | C17: 26 | D17: 11 | E17: 1 | F17: =C17*Supuestos!$C$35+D17*Supuestos!$C$36+E17*Supuestos!$C$37 | G17: =(C17*Supuestos!$B$35+D17*Supuestos!$B$36+E17*Supuestos!$B$37)*Supuestos!$B$52 | H17: =F17*Supuestos!$B$46*Supuestos!$B$52 | I17: =IF(A17<=3,0,Infraestructura!$D$20) | J17: =-Costo_Desarrollo!$D$23*0 | K17: =IF(Supuestos!$B$10=2,Costo_Desarrollo!$G$23*0,0) | L17: =G17-H17-I17+J17+K17 | M17: =M16+L17 | N17: =G17/Supuestos!$B$52*Supuestos!$B$51-F17*Supuestos!$B$46*Supuestos!$B$51-I17+J17+K17 | O17: =O16+N17 | P17: =G17/Supuestos!$B$52*Supuestos!$B$53-F17*Supuestos!$B$46*Supuestos!$B$53-I17+J17+K17 | Q17: =Q16+P17 | R17: =G17-H17-I17 | S17: =G17/Supuestos!$B$52*Supuestos!$B$51-F17*Supuestos!$B$46*Supuestos!$B$51-I17 | T17: =G17/Supuestos!$B$52*Supuestos!$B$53-F17*Supuestos!$B$46*Supuestos!$B$53-I17 | U17: =IF(AND(A17>4,S17>0),1,0) | V17: =IF(AND(A17>4,R17>0),1,0) | W17: =IF(AND(A17>4,T17>0),1,0) | X17: =IF(AND(A17>4,O17>0),1,0) | Y17: =IF(AND(A17>4,M17>0),1,0) | Z17: =IF(AND(A17>4,Q17>0),1,0)
A18: 14 | B18: Operación | C18: 28 | D18: 12 | E18: 1 | F18: =C18*Supuestos!$C$35+D18*Supuestos!$C$36+E18*Supuestos!$C$37 | G18: =(C18*Supuestos!$B$35+D18*Supuestos!$B$36+E18*Supuestos!$B$37)*Supuestos!$B$52 | H18: =F18*Supuestos!$B$46*Supuestos!$B$52 | I18: =IF(A18<=3,0,Infraestructura!$D$20) | J18: =-Costo_Desarrollo!$D$23*0 | K18: =IF(Supuestos!$B$10=2,Costo_Desarrollo!$G$23*0,0) | L18: =G18-H18-I18+J18+K18 | M18: =M17+L18 | N18: =G18/Supuestos!$B$52*Supuestos!$B$51-F18*Supuestos!$B$46*Supuestos!$B$51-I18+J18+K18 | O18: =O17+N18 | P18: =G18/Supuestos!$B$52*Supuestos!$B$53-F18*Supuestos!$B$46*Supuestos!$B$53-I18+J18+K18 | Q18: =Q17+P18 | R18: =G18-H18-I18 | S18: =G18/Supuestos!$B$52*Supuestos!$B$51-F18*Supuestos!$B$46*Supuestos!$B$51-I18 | T18: =G18/Supuestos!$B$52*Supuestos!$B$53-F18*Supuestos!$B$46*Supuestos!$B$53-I18 | U18: =IF(AND(A18>4,S18>0),1,0) | V18: =IF(AND(A18>4,R18>0),1,0) | W18: =IF(AND(A18>4,T18>0),1,0) | X18: =IF(AND(A18>4,O18>0),1,0) | Y18: =IF(AND(A18>4,M18>0),1,0) | Z18: =IF(AND(A18>4,Q18>0),1,0)
A19: 15 | B19: Operación | C19: 30 | D19: 12 | E19: 1 | F19: =C19*Supuestos!$C$35+D19*Supuestos!$C$36+E19*Supuestos!$C$37 | G19: =(C19*Supuestos!$B$35+D19*Supuestos!$B$36+E19*Supuestos!$B$37)*Supuestos!$B$52 | H19: =F19*Supuestos!$B$46*Supuestos!$B$52 | I19: =IF(A19<=3,0,Infraestructura!$D$20) | J19: =-Costo_Desarrollo!$D$23*0 | K19: =IF(Supuestos!$B$10=2,Costo_Desarrollo!$G$23*0,0) | L19: =G19-H19-I19+J19+K19 | M19: =M18+L19 | N19: =G19/Supuestos!$B$52*Supuestos!$B$51-F19*Supuestos!$B$46*Supuestos!$B$51-I19+J19+K19 | O19: =O18+N19 | P19: =G19/Supuestos!$B$52*Supuestos!$B$53-F19*Supuestos!$B$46*Supuestos!$B$53-I19+J19+K19 | Q19: =Q18+P19 | R19: =G19-H19-I19 | S19: =G19/Supuestos!$B$52*Supuestos!$B$51-F19*Supuestos!$B$46*Supuestos!$B$51-I19 | T19: =G19/Supuestos!$B$52*Supuestos!$B$53-F19*Supuestos!$B$46*Supuestos!$B$53-I19 | U19: =IF(AND(A19>4,S19>0),1,0) | V19: =IF(AND(A19>4,R19>0),1,0) | W19: =IF(AND(A19>4,T19>0),1,0) | X19: =IF(AND(A19>4,O19>0),1,0) | Y19: =IF(AND(A19>4,M19>0),1,0) | Z19: =IF(AND(A19>4,Q19>0),1,0)
A20: 16 | B20: Operación | C20: 32 | D20: 13 | E20: 1 | F20: =C20*Supuestos!$C$35+D20*Supuestos!$C$36+E20*Supuestos!$C$37 | G20: =(C20*Supuestos!$B$35+D20*Supuestos!$B$36+E20*Supuestos!$B$37)*Supuestos!$B$52 | H20: =F20*Supuestos!$B$46*Supuestos!$B$52 | I20: =IF(A20<=3,0,Infraestructura!$D$20) | J20: =-Costo_Desarrollo!$D$23*0 | K20: =IF(Supuestos!$B$10=2,Costo_Desarrollo!$G$23*0,0) | L20: =G20-H20-I20+J20+K20 | M20: =M19+L20 | N20: =G20/Supuestos!$B$52*Supuestos!$B$51-F20*Supuestos!$B$46*Supuestos!$B$51-I20+J20+K20 | O20: =O19+N20 | P20: =G20/Supuestos!$B$52*Supuestos!$B$53-F20*Supuestos!$B$46*Supuestos!$B$53-I20+J20+K20 | Q20: =Q19+P20 | R20: =G20-H20-I20 | S20: =G20/Supuestos!$B$52*Supuestos!$B$51-F20*Supuestos!$B$46*Supuestos!$B$51-I20 | T20: =G20/Supuestos!$B$52*Supuestos!$B$53-F20*Supuestos!$B$46*Supuestos!$B$53-I20 | U20: =IF(AND(A20>4,S20>0),1,0) | V20: =IF(AND(A20>4,R20>0),1,0) | W20: =IF(AND(A20>4,T20>0),1,0) | X20: =IF(AND(A20>4,O20>0),1,0) | Y20: =IF(AND(A20>4,M20>0),1,0) | Z20: =IF(AND(A20>4,Q20>0),1,0)
... A40: 36 | B40: Operación | C40: 66 | D40: 25 | E40: 3 | F40: =C40*Supuestos!$C$35+D40*Supuestos!$C$36+E40*Supuestos!$C$37 | G40: =(C40*Supuestos!$B$35+D40*Supuestos!$B$36+E40*Supuestos!$B$37)*Supuestos!$B$52 | H40: =F40*Supuestos!$B$46*Supuestos!$B$52 | I40: =IF(A40<=3,0,Infraestructura!$D$20) | J40: =-Costo_Desarrollo!$D$23*0 | K40: =IF(Supuestos!$B$10=2,Costo_Desarrollo!$G$23*0,0) | L40: =G40-H40-I40+J40+K40 | M40: =M39+L40 | N40: =G40/Supuestos!$B$52*Supuestos!$B$51-F40*Supuestos!$B$46*Supuestos!$B$51-I40+J40+K40 | O40: =O39+N40 | P40: =G40/Supuestos!$B$52*Supuestos!$B$53-F40*Supuestos!$B$46*Supuestos!$B$53-I40+J40+K40 | Q40: =Q39+P40 | R40: =G40-H40-I40 | S40: =G40/Supuestos!$B$52*Supuestos!$B$51-F40*Supuestos!$B$46*Supuestos!$B$51-I40 | T40: =G40/Supuestos!$B$52*Supuestos!$B$53-F40*Supuestos!$B$46*Supuestos!$B$53-I40 | U40: =IF(AND(A40>4,S40>0),1,0) | V40: =IF(AND(A40>4,R40>0),1,0) | W40: =IF(AND(A40>4,T40>0),1,0) | X40: =IF(AND(A40>4,O40>0),1,0) | Y40: =IF(AND(A40>4,M40>0),1,0) | Z40: =IF(AND(A40>4,Q40>0),1,0)
A41: TOTAL | B41: 36 meses | F41: =SUM(F5:F40) | G41: =SUM(G5:G40) | H41: =SUM(H5:H40) | I41: =SUM(I5:I40) | J41: =SUM(J5:J40) | K41: =SUM(K5:K40) | L41: =SUM(L5:L40) | M41: =M40 | N41: =SUM(N5:N40) | O41: =O40 | P41: =SUM(P5:P40) | Q41: =Q40 | R41: =SUM(R5:R40) | S41: =SUM(S5:S40) | T41: =SUM(T5:T40)

Sheet Escenarios
A1: Escenarios y sensibilidad
A2: Mismo modelo, tres velocidades de adopción. El punto de equilibrio es lo que hay que mirar.
A4: Indicador | B4: Conservador | C4: Base | D4: Optimista | E4: Comentario
A5: Factor de adopción | B5: =Supuestos!$B$51 | C5: =Supuestos!$B$52 | D5: =Supuestos!$B$53 | E5: Editable en la hoja Supuestos.
A6: MRR mes 12 (USD) | B6: =Proyeccion_36m!$G$16/Supuestos!$B$52*Supuestos!$B$51 | C6: =Proyeccion_36m!$G$16 | D6: =Proyeccion_36m!$G$16/Supuestos!$B$52*Supuestos!$B$53 | E6: Ingreso recurrente mensual al cerrar el primer año de operación.
A7: MRR mes 24 (USD) | B7: =Proyeccion_36m!$G$28/Supuestos!$B$52*Supuestos!$B$51 | C7: =Proyeccion_36m!$G$28 | D7: =Proyeccion_36m!$G$28/Supuestos!$B$52*Supuestos!$B$53
A8: MRR mes 36 (USD) | B8: =Proyeccion_36m!$G$40/Supuestos!$B$52*Supuestos!$B$51 | C8: =Proyeccion_36m!$G$40 | D8: =Proyeccion_36m!$G$40/Supuestos!$B$52*Supuestos!$B$53
A9: Ingresos acumulados 36 m (USD) | B9: =SUM(Proyeccion_36m!$G$5:$G$40)/Supuestos!$B$52*Supuestos!$B$51 | C9: =SUM(Proyeccion_36m!$G$5:$G$40) | D9: =SUM(Proyeccion_36m!$G$5:$G$40)/Supuestos!$B$52*Supuestos!$B$53
A10: Resultado acumulado 36 m (USD) | B10: =Proyeccion_36m!$O$40 | C10: =Proyeccion_36m!$M$40 | D10: =Proyeccion_36m!$Q$40 | E10: Incluye la inversión de desarrollo según el modelo de negocio elegido.
A11: Resultado acumulado 36 m (PEN) | B11: =Proyeccion_36m!$O$40*Supuestos!$B$5 | C11: =Proyeccion_36m!$M$40*Supuestos!$B$5 | D11: =Proyeccion_36m!$Q$40*Supuestos!$B$5
A12: Mes de equilibrio operativo | B12: =IFERROR(INDEX(Proyeccion_36m!$A$5:$A$40,MATCH(1,Proyeccion_36m!$U$5:$U$40,0)),"> 36") | C12: =IFERROR(INDEX(Proyeccion_36m!$A$5:$A$40,MATCH(1,Proyeccion_36m!$V$5:$V$40,0)),"> 36") | D12: =IFERROR(INDEX(Proyeccion_36m!$A$5:$A$40,MATCH(1,Proyeccion_36m!$W$5:$W$40,0)),"> 36") | E12: Primer mes en que la suscripción cubre infraestructura, soporte y LLM. No cuenta el desarrollo.
A13: Mes de recuperación de la inversión | B13: =IFERROR(INDEX(Proyeccion_36m!$A$5:$A$40,MATCH(1,Proyeccion_36m!$X$5:$X$40,0)),"> 36") | C13: =IFERROR(INDEX(Proyeccion_36m!$A$5:$A$40,MATCH(1,Proyeccion_36m!$Y$5:$Y$40,0)),"> 36") | D13: =IFERROR(INDEX(Proyeccion_36m!$A$5:$A$40,MATCH(1,Proyeccion_36m!$Z$5:$Z$40,0)),"> 36") | E13: Con modelo de negocio 2 (contrato al CITE) el desarrollo lo paga el cliente y no hay inversión que recuperar: sale mes 1. Cambia el modelo a 1 en Supuestos para verlo como producto propio.
A15: SENSIBILIDAD DEL PRESUPUESTO DE DESARROLLO
A16: Variable | B16: -20 % | C16: Valor del modelo | D16: +20 % | E16: Efecto sobre el precio
A17: Factor de aceleración por IA (código) | B17: =Supuestos!$B$21*0.8 | C17: =Supuestos!$B$21 | D17: =Supuestos!$B$21*1.2 | E17: Es la palanca más sensible: mueve el 39 % de las horas del proyecto.
A18: Tarifa de venta del dev senior (USD/h) | B18: =Supuestos!$C$14*0.8 | C18: =Supuestos!$C$14 | D18: =Supuestos!$C$14*1.2 | E18: ±20 % de tarifa ≈ ±14 % de precio total (el resto son otros roles y directos).
A19: Precio del plan Institucional (USD/mes) | B19: =Supuestos!$B$37*0.8 | C19: =Supuestos!$B$37 | D19: =Supuestos!$B$37*1.2 | E19: El contrato del CITE sostiene el punto de equilibrio los primeros 12 meses.
A20: Contingencia del proyecto | B20: =Supuestos!$B$30*0.8 | C20: =Supuestos!$B$30 | D20: =Supuestos!$B$30*1.2 | E20: Riesgos abiertos: Codex bloqueado por robots.txt, p95 de glm-5.2 en 36 s, anti-bot de N2.
A22: RIESGOS QUE PUEDEN MOVER EL PRESUPUESTO
A23: Riesgo | B23: Probabilidad | C23: Impacto (h) | D23: Impacto (USD) | E23: Mitigación
A24: Codex/GSFA no se puede rastrear (robots.txt de la FAO) | B24: Alta | C24: 24 | D24: =C24*Supuestos!$C$14 | E24: Curación manual ya presupuestada; se declara SIN_DATO, nunca 'no autorizado'.
A25: p95 de 36 s en el análisis de aditivos | B25: Confirmada | C25: 16 | D25: =C25*Supuestos!$C$14 | E25: Concurrencia entre aditivos + caché + job con progreso. Ya está en T4/T5.
A26: Anti-bot bloquea tiendas de N2 | B26: Media | C26: 32 | D26: =C26*Supuestos!$C$14 | E26: Bajar a 70 tiendas y mantener el umbral de cobertura declarada.
A27: Huawei cambia la tarificación de MaaS | B27: Baja | C27: 8 | D27: =C27*Supuestos!$C$14 | E27: Cláusula de renegociación si sube > 20 %; fallback a Qwen.
A28: OCR de DIGESA ilegible | B28: Media | C28: 16 | D28: =C28*Supuestos!$C$14 | E28: Pedido formal de datos estructurados a DIGESA; degradar a cita por documento.
A29: El CITE pide multi-tenant con RLS por organización | B29: Media | C29: 40 | D29: =C29*Supuestos!$C$14 | E29: ADR-003 fase 1; es el cambio de alcance más caro que queda abierto.
A30: TOTAL SI TODO SE MATERIALIZA | C30: =SUM(C24:C29) | D30: =SUM(D24:D29) | E30: Comparar con la contingencia del proyecto: si esto supera la contingencia, hay que subirla.
A31: Contingencia presupuestada | C31: =Esfuerzo!$G$59 | D31: =Esfuerzo!$G$59*Supuestos!$C$14

Sheet Hitos_Pago
A1: Cronograma de hitos y facturación
A2: Cinco entregas verificables. Cada hito se cobra contra una prueba que se puede ejecutar delante del cliente.
A4: Hito | B4: Semana | C4: Entregable | D4: Criterio de aceptación | E4: % | F4: USD | G4: PEN
A5: H0 · Firma y arranque | B5: 0 | C5: Kick-off, accesos, entorno de dev y staging aprovisionado | D5: Stack de dev en pie; el equipo del CITE puede entrar al panel de staging. | E5: 0.3 | F5: =$E5*Costo_Desarrollo!$G$23 | G5: =F5*Supuestos!$B$5
A6: H1 · Núcleo asíncrono | B6: 4 | C6: Infraestructura, agente con cuarentena, cola de jobs y motor de tendencias | D6: P11, P12, P13, P16 y P17 en verde; P10 degradada sobre datos reales. | E6: 0.25 | F6: =$E6*Costo_Desarrollo!$G$23 | G6: =F6*Supuestos!$B$5
A7: H2 · Datos y vigilancia | B7: 7 | C7: Corpus regulatorio completo, N2 con Scrapling/Bright Data y alertas de retiro | D7: P08, P14, P18, P19 y P20 en verde; toda cita con URL viva. | E7: 0.25 | F7: =$E7*Costo_Desarrollo!$G$23 | G7: =F7*Supuestos!$B$5
A8: H3 · Producto y confianza | B8: 10 | C8: Promoción automática, panel CITE completo, CI y load testing | D8: P09 y P15 en verde; 50 rps sostenidos con p95 < 2 s; spike de 500 rps degrada sin 5xx. | E8: 0.1 | F8: =$E8*Costo_Desarrollo!$G$23 | G8: =F8*Supuestos!$B$5
A9: H4 · Go-live | B9: 12 | C9: Optimización de modelos, canary, capacitación y runbook | D9: 24 h en producción sin incidentes; equipo del CITE capacitado; rollback probado en < 5 min. | E9: 0.1 | F9: =$E9*Costo_Desarrollo!$G$23 | G9: =F9*Supuestos!$B$5
A10: TOTAL | E10: =SUM(E5:E9) | F10: =SUM(F5:F9) | G10: =SUM(G5:G9)
A11: IGV | F11: =F10*Supuestos!$B$6 | G11: =G10*Supuestos!$B$6
A12: TOTAL CON IGV | F12: =F10+F11 | G12: =G10+G11
A14: El 30 % de arranque cubre las licencias de IA y la infraestructura del primer mes, que son gasto de bolsillo desde el día 1. Los hitos siguientes se pagan contra pruebas ejecutables, no contra documentos.
